2025-07-30 23:10:20,871 - task_service - INFO - Starting RabbitMQ consumer thread...
2025-07-30 23:10:20,871 - task_service - INFO - Attempting to connect to RabbitMQ (Attempt 1/3)
2025-07-30 23:10:20,871 - task_service - INFO - RabbitMQ consumer thread started
2025-07-30 23:10:20,872 - __main__ - INFO - ================================================================================
2025-07-30 23:10:20,872 - __main__ - INFO - Starting Task Updater Service at 2025-07-30 23:10:20.872205
2025-07-30 23:10:20,872 - __main__ - INFO - Service Name: Task Updater Service
2025-07-30 23:10:20,872 - __main__ - INFO - Server running on http://localhost:8002
2025-07-30 23:10:20,872 - __main__ - INFO - RabbitMQ consumer is running in the background
2025-07-30 23:10:20,872 - __main__ - INFO - ================================================================================
2025-07-30 23:10:20,877 - pika.adapters.utils.connection_workflow - INFO - Pika version 1.3.2 connecting to ('::1', 5672, 0, 0)
2025-07-30 23:10:20,880 - pika.adapters.utils.io_services_utils - ERROR - Socket failed to connect: <socket.socket fd=11, family=30, type=1, proto=6, laddr=('::1', 63519, 0, 0)>; error=61 (Connection refused)
2025-07-30 23:10:20,880 - pika.adapters.utils.connection_workflow - ERROR - TCP Connection attempt failed: ConnectionRefusedError(61, 'Connection refused'); dest=(<AddressFamily.AF_INET6: 30>, <SocketKind.SOCK_STREAM: 1>, 6, '', ('::1', 5672, 0, 0))
2025-07-30 23:10:20,880 - pika.adapters.utils.connection_workflow - ERROR - AMQPConnector - reporting failure: AMQPConnectorSocketConnectError: ConnectionRefusedError(61, 'Connection refused')
2025-07-30 23:10:20,880 - pika.adapters.utils.connection_workflow - INFO - Pika version 1.3.2 connecting to ('127.0.0.1', 5672)
2025-07-30 23:10:20,881 - pika.adapters.utils.io_services_utils - INFO - Socket connected: <socket.socket fd=11, family=2, type=1, proto=6, laddr=('127.0.0.1', 63520), raddr=('127.0.0.1', 5672)>
2025-07-30 23:10:20,881 - pika.adapters.utils.connection_workflow - INFO - Streaming transport linked up: (<pika.adapters.utils.io_services_utils._AsyncPlaintextTransport object at 0x1048c0ec0>, _StreamingProtocolShim: <SelectConnection PROTOCOL transport=<pika.adapters.utils.io_services_utils._AsyncPlaintextTransport object at 0x1048c0ec0> params=<ConnectionParameters host=localhost port=5672 virtual_host=/ ssl=False>>).
2025-07-30 23:10:20,898 - pika.adapters.utils.connection_workflow - INFO - AMQPConnector - reporting success: <SelectConnection OPEN transport=<pika.adapters.utils.io_services_utils._AsyncPlaintextTransport object at 0x1048c0ec0> params=<ConnectionParameters host=localhost port=5672 virtual_host=/ ssl=False>>
2025-07-30 23:10:20,899 - pika.adapters.utils.connection_workflow - INFO - AMQPConnectionWorkflow - reporting success: <SelectConnection OPEN transport=<pika.adapters.utils.io_services_utils._AsyncPlaintextTransport object at 0x1048c0ec0> params=<ConnectionParameters host=localhost port=5672 virtual_host=/ ssl=False>>
2025-07-30 23:10:20,899 - pika.adapters.blocking_connection - INFO - Connection workflow succeeded: <SelectConnection OPEN transport=<pika.adapters.utils.io_services_utils._AsyncPlaintextTransport object at 0x1048c0ec0> params=<ConnectionParameters host=localhost port=5672 virtual_host=/ ssl=False>>
2025-07-30 23:10:20,899 - pika.adapters.blocking_connection - INFO - Created channel=1
2025-07-30 23:10:20,902 - pika.channel - WARNING - Received remote Channel.Close (406): "PRECONDITION_FAILED - inequivalent arg 'durable' for queue 'task_consumer_queue' in vhost '/': received 'true' but current is 'false'" on <Channel number=1 OPEN conn=<SelectConnection OPEN transport=<pika.adapters.utils.io_services_utils._AsyncPlaintextTransport object at 0x1048c0ec0> params=<ConnectionParameters host=localhost port=5672 virtual_host=/ ssl=False>>>
2025-07-30 23:10:20,902 - task_service - ERROR - Channel error: (406, "PRECONDITION_FAILED - inequivalent arg 'durable' for queue 'task_consumer_queue' in vhost '/': received 'true' but current is 'false'")
2025-07-30 23:10:20,902 - pika.adapters.blocking_connection - INFO - Closing connection (200): Normal shutdown
2025-07-30 23:10:20,902 - pika.connection - INFO - Closing connection (200): 'Normal shutdown'
2025-07-30 23:10:20,902 - pika.adapters.utils.io_services_utils - INFO - Aborting transport connection: state=1; <socket.socket fd=11, family=2, type=1, proto=6, laddr=('127.0.0.1', 63520), raddr=('127.0.0.1', 5672)>
2025-07-30 23:10:20,902 - pika.adapters.utils.io_services_utils - INFO - _AsyncTransportBase._initate_abort(): Initiating abrupt asynchronous transport shutdown: state=1; error=None; <socket.socket fd=11, family=2, type=1, proto=6, laddr=('127.0.0.1', 63520), raddr=('127.0.0.1', 5672)>
2025-07-30 23:10:20,902 - pika.adapters.utils.io_services_utils - INFO - Deactivating transport: state=1; <socket.socket fd=11, family=2, type=1, proto=6, laddr=('127.0.0.1', 63520), raddr=('127.0.0.1', 5672)>
2025-07-30 23:10:20,902 - pika.connection - INFO - AMQP stack terminated, failed to connect, or aborted: opened=True, error-arg=None; pending-error=ConnectionClosedByClient: (200) 'Normal shutdown'
2025-07-30 23:10:20,902 - pika.connection - INFO - Stack terminated due to ConnectionClosedByClient: (200) 'Normal shutdown'
2025-07-30 23:10:20,903 - pika.adapters.utils.io_services_utils - INFO - Closing transport socket and unlinking: state=3; <socket.socket fd=11, family=2, type=1, proto=6, laddr=('127.0.0.1', 63520), raddr=('127.0.0.1', 5672)>
2025-07-30 23:10:20,903 - pika.adapters.blocking_connection - INFO - User-initiated close: result=BlockingConnection__OnClosedArgs(connection=<SelectConnection CLOSED transport=None params=<ConnectionParameters host=localhost port=5672 virtual_host=/ ssl=False>>, error=ConnectionClosedByClient: (200) 'Normal shutdown')
2025-07-30 23:10:20,903 - task_service - INFO - Closed RabbitMQ connection
2025-07-30 23:11:13,425 - task_service - INFO - Starting RabbitMQ consumer thread...
2025-07-30 23:11:13,425 - task_service - INFO - Attempting to connect to RabbitMQ (Attempt 1/3)
2025-07-30 23:11:13,425 - task_service - INFO - RabbitMQ consumer thread started
2025-07-30 23:11:13,425 - __main__ - INFO - ================================================================================
2025-07-30 23:11:13,425 - __main__ - INFO - Starting Task Updater Service at 2025-07-30 23:11:13.425903
2025-07-30 23:11:13,425 - __main__ - INFO - Service Name: Task Updater Service
2025-07-30 23:11:13,425 - __main__ - INFO - Server running on http://localhost:8002
2025-07-30 23:11:13,425 - __main__ - INFO - RabbitMQ consumer is running in the background
2025-07-30 23:11:13,425 - __main__ - INFO - ================================================================================
2025-07-30 23:11:13,430 - pika.adapters.utils.connection_workflow - INFO - Pika version 1.3.2 connecting to ('::1', 5672, 0, 0)
2025-07-30 23:11:13,430 - pika.adapters.utils.io_services_utils - ERROR - Socket failed to connect: <socket.socket fd=12, family=30, type=1, proto=6, laddr=('::1', 63584, 0, 0)>; error=61 (Connection refused)
2025-07-30 23:11:13,430 - pika.adapters.utils.connection_workflow - ERROR - TCP Connection attempt failed: ConnectionRefusedError(61, 'Connection refused'); dest=(<AddressFamily.AF_INET6: 30>, <SocketKind.SOCK_STREAM: 1>, 6, '', ('::1', 5672, 0, 0))
2025-07-30 23:11:13,430 - pika.adapters.utils.connection_workflow - ERROR - AMQPConnector - reporting failure: AMQPConnectorSocketConnectError: ConnectionRefusedError(61, 'Connection refused')
2025-07-30 23:11:13,430 - pika.adapters.utils.connection_workflow - INFO - Pika version 1.3.2 connecting to ('127.0.0.1', 5672)
2025-07-30 23:11:13,430 - pika.adapters.utils.io_services_utils - INFO - Socket connected: <socket.socket fd=12, family=2, type=1, proto=6, laddr=('127.0.0.1', 63585), raddr=('127.0.0.1', 5672)>
2025-07-30 23:11:13,431 - pika.adapters.utils.connection_workflow - INFO - Streaming transport linked up: (<pika.adapters.utils.io_services_utils._AsyncPlaintextTransport object at 0x1030c7b60>, _StreamingProtocolShim: <SelectConnection PROTOCOL transport=<pika.adapters.utils.io_services_utils._AsyncPlaintextTransport object at 0x1030c7b60> params=<ConnectionParameters host=localhost port=5672 virtual_host=/ ssl=False>>).
2025-07-30 23:11:13,440 - pika.adapters.utils.connection_workflow - INFO - AMQPConnector - reporting success: <SelectConnection OPEN transport=<pika.adapters.utils.io_services_utils._AsyncPlaintextTransport object at 0x1030c7b60> params=<ConnectionParameters host=localhost port=5672 virtual_host=/ ssl=False>>
2025-07-30 23:11:13,440 - pika.adapters.utils.connection_workflow - INFO - AMQPConnectionWorkflow - reporting success: <SelectConnection OPEN transport=<pika.adapters.utils.io_services_utils._AsyncPlaintextTransport object at 0x1030c7b60> params=<ConnectionParameters host=localhost port=5672 virtual_host=/ ssl=False>>
2025-07-30 23:11:13,440 - pika.adapters.blocking_connection - INFO - Connection workflow succeeded: <SelectConnection OPEN transport=<pika.adapters.utils.io_services_utils._AsyncPlaintextTransport object at 0x1030c7b60> params=<ConnectionParameters host=localhost port=5672 virtual_host=/ ssl=False>>
2025-07-30 23:11:13,440 - pika.adapters.blocking_connection - INFO - Created channel=1
2025-07-30 23:11:13,441 - pika.channel - WARNING - Received remote Channel.Close (406): "PRECONDITION_FAILED - inequivalent arg 'durable' for queue 'task_consumer_queue' in vhost '/': received 'true' but current is 'false'" on <Channel number=1 OPEN conn=<SelectConnection OPEN transport=<pika.adapters.utils.io_services_utils._AsyncPlaintextTransport object at 0x1030c7b60> params=<ConnectionParameters host=localhost port=5672 virtual_host=/ ssl=False>>>
2025-07-30 23:11:13,441 - task_service - ERROR - Channel error: (406, "PRECONDITION_FAILED - inequivalent arg 'durable' for queue 'task_consumer_queue' in vhost '/': received 'true' but current is 'false'")
2025-07-30 23:11:13,441 - pika.adapters.blocking_connection - INFO - Closing connection (200): Normal shutdown
2025-07-30 23:11:13,441 - pika.connection - INFO - Closing connection (200): 'Normal shutdown'
2025-07-30 23:11:13,442 - pika.adapters.utils.io_services_utils - INFO - Aborting transport connection: state=1; <socket.socket fd=12, family=2, type=1, proto=6, laddr=('127.0.0.1', 63585), raddr=('127.0.0.1', 5672)>
2025-07-30 23:11:13,442 - pika.adapters.utils.io_services_utils - INFO - _AsyncTransportBase._initate_abort(): Initiating abrupt asynchronous transport shutdown: state=1; error=None; <socket.socket fd=12, family=2, type=1, proto=6, laddr=('127.0.0.1', 63585), raddr=('127.0.0.1', 5672)>
2025-07-30 23:11:13,442 - pika.adapters.utils.io_services_utils - INFO - Deactivating transport: state=1; <socket.socket fd=12, family=2, type=1, proto=6, laddr=('127.0.0.1', 63585), raddr=('127.0.0.1', 5672)>
2025-07-30 23:11:13,442 - pika.connection - INFO - AMQP stack terminated, failed to connect, or aborted: opened=True, error-arg=None; pending-error=ConnectionClosedByClient: (200) 'Normal shutdown'
2025-07-30 23:11:13,442 - pika.connection - INFO - Stack terminated due to ConnectionClosedByClient: (200) 'Normal shutdown'
2025-07-30 23:11:13,442 - pika.adapters.utils.io_services_utils - INFO - Closing transport socket and unlinking: state=3; <socket.socket fd=12, family=2, type=1, proto=6, laddr=('127.0.0.1', 63585), raddr=('127.0.0.1', 5672)>
2025-07-30 23:11:13,442 - pika.adapters.blocking_connection - INFO - User-initiated close: result=BlockingConnection__OnClosedArgs(connection=<SelectConnection CLOSED transport=None params=<ConnectionParameters host=localhost port=5672 virtual_host=/ ssl=False>>, error=ConnectionClosedByClient: (200) 'Normal shutdown')
2025-07-30 23:11:13,442 - task_service - INFO - Closed RabbitMQ connection
2025-07-30 23:15:29,551 - task_service - INFO - Starting RabbitMQ consumer thread...
2025-07-30 23:15:29,552 - task_service - INFO - Attempting to connect to RabbitMQ (Attempt 1/3)
2025-07-30 23:15:29,552 - task_service - INFO - RabbitMQ consumer thread started
2025-07-30 23:15:29,552 - __main__ - INFO - ================================================================================
2025-07-30 23:15:29,552 - __main__ - INFO - Starting Task Updater Service at 2025-07-30 23:15:29.552665
2025-07-30 23:15:29,552 - __main__ - INFO - Service Name: Task Updater Service
2025-07-30 23:15:29,552 - __main__ - INFO - Server running on http://localhost:8002
2025-07-30 23:15:29,552 - __main__ - INFO - RabbitMQ consumer is running in the background
2025-07-30 23:15:29,552 - __main__ - INFO - ================================================================================
2025-07-30 23:15:29,556 - pika.adapters.utils.connection_workflow - INFO - Pika version 1.3.2 connecting to ('::1', 5672, 0, 0)
2025-07-30 23:15:29,557 - pika.adapters.utils.io_services_utils - ERROR - Socket failed to connect: <socket.socket fd=12, family=30, type=1, proto=6, laddr=('::1', 63906, 0, 0)>; error=61 (Connection refused)
2025-07-30 23:15:29,557 - pika.adapters.utils.connection_workflow - ERROR - TCP Connection attempt failed: ConnectionRefusedError(61, 'Connection refused'); dest=(<AddressFamily.AF_INET6: 30>, <SocketKind.SOCK_STREAM: 1>, 6, '', ('::1', 5672, 0, 0))
2025-07-30 23:15:29,557 - pika.adapters.utils.connection_workflow - ERROR - AMQPConnector - reporting failure: AMQPConnectorSocketConnectError: ConnectionRefusedError(61, 'Connection refused')
2025-07-30 23:15:29,557 - pika.adapters.utils.connection_workflow - INFO - Pika version 1.3.2 connecting to ('127.0.0.1', 5672)
2025-07-30 23:15:29,557 - pika.adapters.utils.io_services_utils - INFO - Socket connected: <socket.socket fd=12, family=2, type=1, proto=6, laddr=('127.0.0.1', 63907), raddr=('127.0.0.1', 5672)>
2025-07-30 23:15:29,557 - pika.adapters.utils.connection_workflow - INFO - Streaming transport linked up: (<pika.adapters.utils.io_services_utils._AsyncPlaintextTransport object at 0x105cc6510>, _StreamingProtocolShim: <SelectConnection PROTOCOL transport=<pika.adapters.utils.io_services_utils._AsyncPlaintextTransport object at 0x105cc6510> params=<ConnectionParameters host=localhost port=5672 virtual_host=/ ssl=False>>).
2025-07-30 23:15:29,566 - pika.adapters.utils.connection_workflow - INFO - AMQPConnector - reporting success: <SelectConnection OPEN transport=<pika.adapters.utils.io_services_utils._AsyncPlaintextTransport object at 0x105cc6510> params=<ConnectionParameters host=localhost port=5672 virtual_host=/ ssl=False>>
2025-07-30 23:15:29,566 - pika.adapters.utils.connection_workflow - INFO - AMQPConnectionWorkflow - reporting success: <SelectConnection OPEN transport=<pika.adapters.utils.io_services_utils._AsyncPlaintextTransport object at 0x105cc6510> params=<ConnectionParameters host=localhost port=5672 virtual_host=/ ssl=False>>
2025-07-30 23:15:29,566 - pika.adapters.blocking_connection - INFO - Connection workflow succeeded: <SelectConnection OPEN transport=<pika.adapters.utils.io_services_utils._AsyncPlaintextTransport object at 0x105cc6510> params=<ConnectionParameters host=localhost port=5672 virtual_host=/ ssl=False>>
2025-07-30 23:15:29,566 - pika.adapters.blocking_connection - INFO - Created channel=1
2025-07-30 23:15:29,568 - task_service - INFO - Successfully connected to RabbitMQ
2025-07-30 23:15:29,569 - task_service - INFO - Listening for messages on queue: task_consumer_queue
2025-07-30 23:15:29,569 - task_service - INFO - Press CTRL+C to exit
2025-07-30 23:15:29,569 - task_service - INFO - Processing message - Task ID: e66e4e08-27b7-4f41-b811-7b981ee36264, Action: create
2025-07-30 23:15:29,569 - task_service - INFO - Creating/Updating task - ID: e66e4e08-27b7-4f41-b811-7b981ee36264
2025-07-30 23:15:29,569 - task_service - INFO - Task Name: hoalsad
2025-07-30 23:15:29,569 - task_service - INFO - Assignee: sa;lkfasdf
2025-07-30 23:15:29,569 - task_service - INFO - Successfully processed message for task ID: e66e4e08-27b7-4f41-b811-7b981ee36264
2025-07-30 23:15:29,569 - task_service - INFO - Processing message - Task ID: e66e4e08-27b7-4f41-b811-7b981ee36264, Action: delete
2025-07-30 23:15:29,569 - task_service - INFO - Deleting task - ID: e66e4e08-27b7-4f41-b811-7b981ee36264
2025-07-30 23:15:29,569 - task_service - INFO - Successfully processed message for task ID: e66e4e08-27b7-4f41-b811-7b981ee36264
2025-07-30 23:15:29,569 - task_service - INFO - Processing message - Task ID: 6e441458-03e8-4d18-9b2f-4dac6a68ee1c, Action: create
2025-07-30 23:15:29,569 - task_service - INFO - Creating/Updating task - ID: 6e441458-03e8-4d18-9b2f-4dac6a68ee1c
2025-07-30 23:15:29,569 - task_service - INFO - Task Name: hola
2025-07-30 23:15:29,569 - task_service - INFO - Assignee: kljshdfa
2025-07-30 23:15:29,569 - task_service - INFO - Successfully processed message for task ID: 6e441458-03e8-4d18-9b2f-4dac6a68ee1c
2025-07-30 23:15:29,570 - task_service - INFO - Processing message - Task ID: 6e441458-03e8-4d18-9b2f-4dac6a68ee1c, Action: delete
2025-07-30 23:15:29,570 - task_service - INFO - Deleting task - ID: 6e441458-03e8-4d18-9b2f-4dac6a68ee1c
2025-07-30 23:15:29,570 - task_service - INFO - Successfully processed message for task ID: 6e441458-03e8-4d18-9b2f-4dac6a68ee1c
2025-07-30 23:17:59,982 - task_service - INFO - Processing message - Task ID: fd86f35e-3533-48e4-b46b-1b6d875bd74c, Action: create
2025-07-30 23:17:59,983 - task_service - INFO - Creating/Updating task - ID: fd86f35e-3533-48e4-b46b-1b6d875bd74c
2025-07-30 23:17:59,984 - task_service - INFO - Task Name: un ticket
2025-07-30 23:17:59,984 - task_service - INFO - Assignee: y es asignado a
2025-07-30 23:17:59,985 - task_service - INFO - Successfully processed message for task ID: fd86f35e-3533-48e4-b46b-1b6d875bd74c
2025-07-30 23:19:20,534 - task_service - INFO - Starting RabbitMQ consumer thread...
2025-07-30 23:19:20,535 - task_service - INFO - Attempting to connect to RabbitMQ (Attempt 1/3)
2025-07-30 23:19:20,535 - task_service - INFO - RabbitMQ consumer thread started
2025-07-30 23:19:20,535 - __main__ - INFO - ================================================================================
2025-07-30 23:19:20,535 - __main__ - INFO - Starting Task Updater Service at 2025-07-30 23:19:20.535655
2025-07-30 23:19:20,535 - __main__ - INFO - Service Name: Task Updater Service
2025-07-30 23:19:20,535 - __main__ - INFO - Server running on http://localhost:8002
2025-07-30 23:19:20,535 - __main__ - INFO - RabbitMQ consumer is running in the background
2025-07-30 23:19:20,535 - __main__ - INFO - ================================================================================
2025-07-30 23:19:20,540 - pika.adapters.utils.connection_workflow - INFO - Pika version 1.3.2 connecting to ('::1', 5672, 0, 0)
2025-07-30 23:19:20,541 - pika.adapters.utils.io_services_utils - ERROR - Socket failed to connect: <socket.socket fd=11, family=30, type=1, proto=6, laddr=('::1', 64227, 0, 0)>; error=61 (Connection refused)
2025-07-30 23:19:20,541 - pika.adapters.utils.connection_workflow - ERROR - TCP Connection attempt failed: ConnectionRefusedError(61, 'Connection refused'); dest=(<AddressFamily.AF_INET6: 30>, <SocketKind.SOCK_STREAM: 1>, 6, '', ('::1', 5672, 0, 0))
2025-07-30 23:19:20,541 - pika.adapters.utils.connection_workflow - ERROR - AMQPConnector - reporting failure: AMQPConnectorSocketConnectError: ConnectionRefusedError(61, 'Connection refused')
2025-07-30 23:19:20,542 - pika.adapters.utils.connection_workflow - INFO - Pika version 1.3.2 connecting to ('127.0.0.1', 5672)
2025-07-30 23:19:20,542 - pika.adapters.utils.io_services_utils - INFO - Socket connected: <socket.socket fd=11, family=2, type=1, proto=6, laddr=('127.0.0.1', 64228), raddr=('127.0.0.1', 5672)>
2025-07-30 23:19:20,542 - pika.adapters.utils.connection_workflow - INFO - Streaming transport linked up: (<pika.adapters.utils.io_services_utils._AsyncPlaintextTransport object at 0x106bc8440>, _StreamingProtocolShim: <SelectConnection PROTOCOL transport=<pika.adapters.utils.io_services_utils._AsyncPlaintextTransport object at 0x106bc8440> params=<ConnectionParameters host=localhost port=5672 virtual_host=/ ssl=False>>).
2025-07-30 23:19:20,550 - pika.adapters.utils.connection_workflow - INFO - AMQPConnector - reporting success: <SelectConnection OPEN transport=<pika.adapters.utils.io_services_utils._AsyncPlaintextTransport object at 0x106bc8440> params=<ConnectionParameters host=localhost port=5672 virtual_host=/ ssl=False>>
2025-07-30 23:19:20,550 - pika.adapters.utils.connection_workflow - INFO - AMQPConnectionWorkflow - reporting success: <SelectConnection OPEN transport=<pika.adapters.utils.io_services_utils._AsyncPlaintextTransport object at 0x106bc8440> params=<ConnectionParameters host=localhost port=5672 virtual_host=/ ssl=False>>
2025-07-30 23:19:20,551 - pika.adapters.blocking_connection - INFO - Connection workflow succeeded: <SelectConnection OPEN transport=<pika.adapters.utils.io_services_utils._AsyncPlaintextTransport object at 0x106bc8440> params=<ConnectionParameters host=localhost port=5672 virtual_host=/ ssl=False>>
2025-07-30 23:19:20,551 - pika.adapters.blocking_connection - INFO - Created channel=1
2025-07-30 23:19:20,552 - task_service - INFO - Successfully connected to RabbitMQ
2025-07-30 23:19:20,552 - task_service - INFO - Listening for messages on queue: task_consumer_queue
2025-07-30 23:19:20,552 - task_service - INFO - Press CTRL+C to exit
2025-07-30 23:19:31,602 - task_service - INFO - Processing message - Task ID: b5dd3e54-2e18-4de1-95fe-e0fb3df56c15, Action: create
2025-07-30 23:19:31,602 - task_service - INFO - Creating/Updating task - ID: b5dd3e54-2e18-4de1-95fe-e0fb3df56c15
2025-07-30 23:19:31,602 - task_service - INFO - Task Name: sarasa
2025-07-30 23:19:31,602 - task_service - INFO - Description: ceresa
2025-07-30 23:19:31,602 - task_service - INFO - Assignee: zaragosa
2025-07-30 23:19:31,602 - task_service - INFO - Successfully processed message for task ID: b5dd3e54-2e18-4de1-95fe-e0fb3df56c15
2025-07-30 23:19:36,711 - task_service - INFO - Processing message - Task ID: b5dd3e54-2e18-4de1-95fe-e0fb3df56c15, Action: delete
2025-07-30 23:19:36,711 - task_service - INFO - Deleting task - ID: b5dd3e54-2e18-4de1-95fe-e0fb3df56c15
2025-07-30 23:19:36,711 - task_service - INFO - Successfully processed message for task ID: b5dd3e54-2e18-4de1-95fe-e0fb3df56c15
2025-07-30 23:34:20,627 - task_service - INFO - Starting RabbitMQ consumer thread...
2025-07-30 23:34:20,627 - task_service - INFO - Attempting to connect to RabbitMQ (Attempt 1/3)
2025-07-30 23:34:20,627 - task_service - INFO - RabbitMQ consumer thread started
2025-07-30 23:34:20,627 - __main__ - INFO - ================================================================================
2025-07-30 23:34:20,628 - __main__ - INFO - Starting Task Updater Service at 2025-07-30 23:34:20.628051
2025-07-30 23:34:20,628 - __main__ - INFO - Service Name: Task Updater Service
2025-07-30 23:34:20,628 - __main__ - INFO - Server running on http://localhost:8002
2025-07-30 23:34:20,628 - __main__ - INFO - RabbitMQ consumer is running in the background
2025-07-30 23:34:20,628 - __main__ - INFO - ================================================================================
2025-07-30 23:34:20,632 - pika.adapters.utils.connection_workflow - INFO - Pika version 1.3.2 connecting to ('::1', 5672, 0, 0)
2025-07-30 23:34:20,632 - pika.adapters.utils.io_services_utils - ERROR - Socket failed to connect: <socket.socket fd=12, family=30, type=1, proto=6, laddr=('::1', 49811, 0, 0)>; error=61 (Connection refused)
2025-07-30 23:34:20,632 - pika.adapters.utils.connection_workflow - ERROR - TCP Connection attempt failed: ConnectionRefusedError(61, 'Connection refused'); dest=(<AddressFamily.AF_INET6: 30>, <SocketKind.SOCK_STREAM: 1>, 6, '', ('::1', 5672, 0, 0))
2025-07-30 23:34:20,632 - pika.adapters.utils.connection_workflow - ERROR - AMQPConnector - reporting failure: AMQPConnectorSocketConnectError: ConnectionRefusedError(61, 'Connection refused')
2025-07-30 23:34:20,632 - pika.adapters.utils.connection_workflow - INFO - Pika version 1.3.2 connecting to ('127.0.0.1', 5672)
2025-07-30 23:34:20,633 - pika.adapters.utils.io_services_utils - INFO - Socket connected: <socket.socket fd=12, family=2, type=1, proto=6, laddr=('127.0.0.1', 49812), raddr=('127.0.0.1', 5672)>
2025-07-30 23:34:20,633 - pika.adapters.utils.connection_workflow - INFO - Streaming transport linked up: (<pika.adapters.utils.io_services_utils._AsyncPlaintextTransport object at 0x105d541a0>, _StreamingProtocolShim: <SelectConnection PROTOCOL transport=<pika.adapters.utils.io_services_utils._AsyncPlaintextTransport object at 0x105d541a0> params=<ConnectionParameters host=localhost port=5672 virtual_host=/ ssl=False>>).
2025-07-30 23:34:20,645 - pika.adapters.utils.connection_workflow - INFO - AMQPConnector - reporting success: <SelectConnection OPEN transport=<pika.adapters.utils.io_services_utils._AsyncPlaintextTransport object at 0x105d541a0> params=<ConnectionParameters host=localhost port=5672 virtual_host=/ ssl=False>>
2025-07-30 23:34:20,645 - pika.adapters.utils.connection_workflow - INFO - AMQPConnectionWorkflow - reporting success: <SelectConnection OPEN transport=<pika.adapters.utils.io_services_utils._AsyncPlaintextTransport object at 0x105d541a0> params=<ConnectionParameters host=localhost port=5672 virtual_host=/ ssl=False>>
2025-07-30 23:34:20,645 - pika.adapters.blocking_connection - INFO - Connection workflow succeeded: <SelectConnection OPEN transport=<pika.adapters.utils.io_services_utils._AsyncPlaintextTransport object at 0x105d541a0> params=<ConnectionParameters host=localhost port=5672 virtual_host=/ ssl=False>>
2025-07-30 23:34:20,645 - pika.adapters.blocking_connection - INFO - Created channel=1
2025-07-30 23:34:20,646 - task_service - INFO - Successfully connected to RabbitMQ
2025-07-30 23:34:20,647 - task_service - INFO - Listening for messages on queue: task_consumer_queue
2025-07-30 23:34:20,647 - task_service - INFO - Press CTRL+C to exit
2025-07-30 23:37:06,131 - task_service - INFO - Starting RabbitMQ consumer thread...
2025-07-30 23:37:06,132 - task_service - INFO - Attempting to connect to RabbitMQ (Attempt 1/3)
2025-07-30 23:37:06,132 - task_service - INFO - RabbitMQ consumer thread started
2025-07-30 23:37:06,132 - __main__ - INFO - ================================================================================
2025-07-30 23:37:06,132 - __main__ - INFO - Starting Task Updater Service at 2025-07-30 23:37:06.132800
2025-07-30 23:37:06,132 - __main__ - INFO - Service Name: Task Updater Service
2025-07-30 23:37:06,132 - __main__ - INFO - Server running on http://localhost:8002
2025-07-30 23:37:06,132 - __main__ - INFO - RabbitMQ consumer is running in the background
2025-07-30 23:37:06,132 - __main__ - INFO - ================================================================================
2025-07-30 23:37:06,136 - pika.adapters.utils.connection_workflow - INFO - Pika version 1.3.2 connecting to ('::1', 5672, 0, 0)
2025-07-30 23:37:06,136 - pika.adapters.utils.io_services_utils - ERROR - Socket failed to connect: <socket.socket fd=12, family=30, type=1, proto=6, laddr=('::1', 50383, 0, 0)>; error=61 (Connection refused)
2025-07-30 23:37:06,136 - pika.adapters.utils.connection_workflow - ERROR - TCP Connection attempt failed: ConnectionRefusedError(61, 'Connection refused'); dest=(<AddressFamily.AF_INET6: 30>, <SocketKind.SOCK_STREAM: 1>, 6, '', ('::1', 5672, 0, 0))
2025-07-30 23:37:06,136 - pika.adapters.utils.connection_workflow - ERROR - AMQPConnector - reporting failure: AMQPConnectorSocketConnectError: ConnectionRefusedError(61, 'Connection refused')
2025-07-30 23:37:06,136 - pika.adapters.utils.connection_workflow - INFO - Pika version 1.3.2 connecting to ('127.0.0.1', 5672)
2025-07-30 23:37:06,137 - pika.adapters.utils.io_services_utils - INFO - Socket connected: <socket.socket fd=12, family=2, type=1, proto=6, laddr=('127.0.0.1', 50384), raddr=('127.0.0.1', 5672)>
2025-07-30 23:37:06,137 - pika.adapters.utils.connection_workflow - INFO - Streaming transport linked up: (<pika.adapters.utils.io_services_utils._AsyncPlaintextTransport object at 0x104717b60>, _StreamingProtocolShim: <SelectConnection PROTOCOL transport=<pika.adapters.utils.io_services_utils._AsyncPlaintextTransport object at 0x104717b60> params=<ConnectionParameters host=localhost port=5672 virtual_host=/ ssl=False>>).
2025-07-30 23:37:06,145 - pika.adapters.utils.connection_workflow - INFO - AMQPConnector - reporting success: <SelectConnection OPEN transport=<pika.adapters.utils.io_services_utils._AsyncPlaintextTransport object at 0x104717b60> params=<ConnectionParameters host=localhost port=5672 virtual_host=/ ssl=False>>
2025-07-30 23:37:06,146 - pika.adapters.utils.connection_workflow - INFO - AMQPConnectionWorkflow - reporting success: <SelectConnection OPEN transport=<pika.adapters.utils.io_services_utils._AsyncPlaintextTransport object at 0x104717b60> params=<ConnectionParameters host=localhost port=5672 virtual_host=/ ssl=False>>
2025-07-30 23:37:06,146 - pika.adapters.blocking_connection - INFO - Connection workflow succeeded: <SelectConnection OPEN transport=<pika.adapters.utils.io_services_utils._AsyncPlaintextTransport object at 0x104717b60> params=<ConnectionParameters host=localhost port=5672 virtual_host=/ ssl=False>>
2025-07-30 23:37:06,146 - pika.adapters.blocking_connection - INFO - Created channel=1
2025-07-30 23:37:06,147 - task_service - INFO - Successfully connected to RabbitMQ
2025-07-30 23:37:06,147 - task_service - INFO - Listening for messages on queue: task_consumer_queue
2025-07-30 23:37:06,147 - task_service - INFO - Press CTRL+C to exit
2025-07-30 23:47:55,874 - task_service - INFO - Starting RabbitMQ consumer thread...
2025-07-30 23:47:55,875 - task_service - INFO - Attempting to connect to RabbitMQ (Attempt 1/3)
2025-07-30 23:47:55,875 - task_service - INFO - RabbitMQ consumer thread started
2025-07-30 23:47:55,875 - __main__ - INFO - ================================================================================
2025-07-30 23:47:55,875 - __main__ - INFO - Starting Task Updater Service at 2025-07-30 23:47:55.875892
2025-07-30 23:47:55,875 - __main__ - INFO - Service Name: Task Updater Service
2025-07-30 23:47:55,875 - __main__ - INFO - Server running on http://localhost:8002
2025-07-30 23:47:55,875 - __main__ - INFO - RabbitMQ consumer is running in the background
2025-07-30 23:47:55,875 - __main__ - INFO - ================================================================================
2025-07-30 23:47:55,879 - pika.adapters.utils.connection_workflow - INFO - Pika version 1.3.2 connecting to ('::1', 5672, 0, 0)
2025-07-30 23:47:55,879 - pika.adapters.utils.io_services_utils - ERROR - Socket failed to connect: <socket.socket fd=12, family=30, type=1, proto=6, laddr=('::1', 51321, 0, 0)>; error=61 (Connection refused)
2025-07-30 23:47:55,879 - pika.adapters.utils.connection_workflow - ERROR - TCP Connection attempt failed: ConnectionRefusedError(61, 'Connection refused'); dest=(<AddressFamily.AF_INET6: 30>, <SocketKind.SOCK_STREAM: 1>, 6, '', ('::1', 5672, 0, 0))
2025-07-30 23:47:55,879 - pika.adapters.utils.connection_workflow - ERROR - AMQPConnector - reporting failure: AMQPConnectorSocketConnectError: ConnectionRefusedError(61, 'Connection refused')
2025-07-30 23:47:55,879 - pika.adapters.utils.connection_workflow - INFO - Pika version 1.3.2 connecting to ('127.0.0.1', 5672)
2025-07-30 23:47:55,879 - pika.adapters.utils.io_services_utils - INFO - Socket connected: <socket.socket fd=12, family=2, type=1, proto=6, laddr=('127.0.0.1', 51322), raddr=('127.0.0.1', 5672)>
2025-07-30 23:47:55,880 - pika.adapters.utils.connection_workflow - INFO - Streaming transport linked up: (<pika.adapters.utils.io_services_utils._AsyncPlaintextTransport object at 0x1047be7b0>, _StreamingProtocolShim: <SelectConnection PROTOCOL transport=<pika.adapters.utils.io_services_utils._AsyncPlaintextTransport object at 0x1047be7b0> params=<ConnectionParameters host=localhost port=5672 virtual_host=/ ssl=False>>).
2025-07-30 23:47:55,889 - pika.adapters.utils.connection_workflow - INFO - AMQPConnector - reporting success: <SelectConnection OPEN transport=<pika.adapters.utils.io_services_utils._AsyncPlaintextTransport object at 0x1047be7b0> params=<ConnectionParameters host=localhost port=5672 virtual_host=/ ssl=False>>
2025-07-30 23:47:55,889 - pika.adapters.utils.connection_workflow - INFO - AMQPConnectionWorkflow - reporting success: <SelectConnection OPEN transport=<pika.adapters.utils.io_services_utils._AsyncPlaintextTransport object at 0x1047be7b0> params=<ConnectionParameters host=localhost port=5672 virtual_host=/ ssl=False>>
2025-07-30 23:47:55,889 - pika.adapters.blocking_connection - INFO - Connection workflow succeeded: <SelectConnection OPEN transport=<pika.adapters.utils.io_services_utils._AsyncPlaintextTransport object at 0x1047be7b0> params=<ConnectionParameters host=localhost port=5672 virtual_host=/ ssl=False>>
2025-07-30 23:47:55,889 - pika.adapters.blocking_connection - INFO - Created channel=1
2025-07-30 23:47:55,890 - task_service - INFO - Successfully connected to RabbitMQ
2025-07-30 23:47:55,890 - task_service - INFO - Listening for messages on queue: task_consumer_queue
2025-07-30 23:47:55,890 - task_service - INFO - Press CTRL+C to exit
2025-07-30 23:48:27,657 - task_service - INFO - Processing message - Task ID: b650a2e4-3589-434f-89eb-b3e91e5456d3, Action: create
2025-07-30 23:48:27,658 - task_service - INFO - Creating/Updating task - ID: b650a2e4-3589-434f-89eb-b3e91e5456d3
2025-07-30 23:48:27,659 - task_service - INFO - Task Name: hola
2025-07-30 23:48:27,659 - task_service - INFO - Description: mi nombre es 
2025-07-30 23:48:27,659 - task_service - INFO - Assignee: manola
2025-07-30 23:48:27,660 - task_service - INFO - Successfully processed message for task ID: b650a2e4-3589-434f-89eb-b3e91e5456d3
2025-07-30 23:51:32,283 - task_service - INFO - Starting RabbitMQ consumer thread...
2025-07-30 23:51:32,283 - task_service - INFO - Attempting to connect to RabbitMQ (Attempt 1/3)
2025-07-30 23:51:32,283 - task_service - INFO - RabbitMQ consumer thread started
2025-07-30 23:51:32,284 - __main__ - INFO - ================================================================================
2025-07-30 23:51:32,284 - __main__ - INFO - Starting Task Updater Service at 2025-07-30 23:51:32.284085
2025-07-30 23:51:32,284 - __main__ - INFO - Service Name: Task Updater Service
2025-07-30 23:51:32,284 - __main__ - INFO - Server running on http://localhost:8002
2025-07-30 23:51:32,284 - __main__ - INFO - RabbitMQ consumer is running in the background
2025-07-30 23:51:32,284 - __main__ - INFO - ================================================================================
2025-07-30 23:51:32,287 - pika.adapters.utils.connection_workflow - INFO - Pika version 1.3.2 connecting to ('::1', 5672, 0, 0)
2025-07-30 23:51:32,288 - pika.adapters.utils.io_services_utils - ERROR - Socket failed to connect: <socket.socket fd=12, family=30, type=1, proto=6, laddr=('::1', 51641, 0, 0)>; error=61 (Connection refused)
2025-07-30 23:51:32,288 - pika.adapters.utils.connection_workflow - ERROR - TCP Connection attempt failed: ConnectionRefusedError(61, 'Connection refused'); dest=(<AddressFamily.AF_INET6: 30>, <SocketKind.SOCK_STREAM: 1>, 6, '', ('::1', 5672, 0, 0))
2025-07-30 23:51:32,288 - pika.adapters.utils.connection_workflow - ERROR - AMQPConnector - reporting failure: AMQPConnectorSocketConnectError: ConnectionRefusedError(61, 'Connection refused')
2025-07-30 23:51:32,288 - pika.adapters.utils.connection_workflow - INFO - Pika version 1.3.2 connecting to ('127.0.0.1', 5672)
2025-07-30 23:51:32,288 - pika.adapters.utils.io_services_utils - INFO - Socket connected: <socket.socket fd=10, family=2, type=1, proto=6, laddr=('127.0.0.1', 51642), raddr=('127.0.0.1', 5672)>
2025-07-30 23:51:32,288 - pika.adapters.utils.connection_workflow - INFO - Streaming transport linked up: (<pika.adapters.utils.io_services_utils._AsyncPlaintextTransport object at 0x102e1bb60>, _StreamingProtocolShim: <SelectConnection PROTOCOL transport=<pika.adapters.utils.io_services_utils._AsyncPlaintextTransport object at 0x102e1bb60> params=<ConnectionParameters host=localhost port=5672 virtual_host=/ ssl=False>>).
2025-07-30 23:51:32,297 - pika.adapters.utils.connection_workflow - INFO - AMQPConnector - reporting success: <SelectConnection OPEN transport=<pika.adapters.utils.io_services_utils._AsyncPlaintextTransport object at 0x102e1bb60> params=<ConnectionParameters host=localhost port=5672 virtual_host=/ ssl=False>>
2025-07-30 23:51:32,297 - pika.adapters.utils.connection_workflow - INFO - AMQPConnectionWorkflow - reporting success: <SelectConnection OPEN transport=<pika.adapters.utils.io_services_utils._AsyncPlaintextTransport object at 0x102e1bb60> params=<ConnectionParameters host=localhost port=5672 virtual_host=/ ssl=False>>
2025-07-30 23:51:32,297 - pika.adapters.blocking_connection - INFO - Connection workflow succeeded: <SelectConnection OPEN transport=<pika.adapters.utils.io_services_utils._AsyncPlaintextTransport object at 0x102e1bb60> params=<ConnectionParameters host=localhost port=5672 virtual_host=/ ssl=False>>
2025-07-30 23:51:32,297 - pika.adapters.blocking_connection - INFO - Created channel=1
2025-07-30 23:51:32,298 - task_service - INFO - Successfully connected to RabbitMQ
2025-07-30 23:51:32,298 - task_service - INFO - Listening for messages on queue: task_consumer_queue
2025-07-30 23:51:32,299 - task_service - INFO - Press CTRL+C to exit
2025-07-30 23:54:01,184 - task_service - INFO - Starting RabbitMQ consumer thread...
2025-07-30 23:54:01,184 - task_service - INFO - Attempting to connect to RabbitMQ (Attempt 1/3)
2025-07-30 23:54:01,184 - task_service - INFO - RabbitMQ consumer thread started
2025-07-30 23:54:01,185 - __main__ - INFO - ================================================================================
2025-07-30 23:54:01,185 - __main__ - INFO - Starting Task Updater Service at 2025-07-30 23:54:01.185209
2025-07-30 23:54:01,185 - __main__ - INFO - Service Name: Task Updater Service
2025-07-30 23:54:01,185 - __main__ - INFO - Server running on http://localhost:8002
2025-07-30 23:54:01,185 - __main__ - INFO - RabbitMQ consumer is running in the background
2025-07-30 23:54:01,185 - __main__ - INFO - ================================================================================
2025-07-30 23:54:01,188 - pika.adapters.utils.connection_workflow - INFO - Pika version 1.3.2 connecting to ('::1', 5672, 0, 0)
2025-07-30 23:54:01,189 - pika.adapters.utils.io_services_utils - ERROR - Socket failed to connect: <socket.socket fd=12, family=30, type=1, proto=6, laddr=('::1', 51872, 0, 0)>; error=61 (Connection refused)
2025-07-30 23:54:01,189 - pika.adapters.utils.connection_workflow - ERROR - TCP Connection attempt failed: ConnectionRefusedError(61, 'Connection refused'); dest=(<AddressFamily.AF_INET6: 30>, <SocketKind.SOCK_STREAM: 1>, 6, '', ('::1', 5672, 0, 0))
2025-07-30 23:54:01,189 - pika.adapters.utils.connection_workflow - ERROR - AMQPConnector - reporting failure: AMQPConnectorSocketConnectError: ConnectionRefusedError(61, 'Connection refused')
2025-07-30 23:54:01,189 - pika.adapters.utils.connection_workflow - INFO - Pika version 1.3.2 connecting to ('127.0.0.1', 5672)
2025-07-30 23:54:01,189 - pika.adapters.utils.io_services_utils - INFO - Socket connected: <socket.socket fd=12, family=2, type=1, proto=6, laddr=('127.0.0.1', 51873), raddr=('127.0.0.1', 5672)>
2025-07-30 23:54:01,189 - pika.adapters.utils.connection_workflow - INFO - Streaming transport linked up: (<pika.adapters.utils.io_services_utils._AsyncPlaintextTransport object at 0x1051c7b60>, _StreamingProtocolShim: <SelectConnection PROTOCOL transport=<pika.adapters.utils.io_services_utils._AsyncPlaintextTransport object at 0x1051c7b60> params=<ConnectionParameters host=localhost port=5672 virtual_host=/ ssl=False>>).
2025-07-30 23:54:01,199 - pika.adapters.utils.connection_workflow - INFO - AMQPConnector - reporting success: <SelectConnection OPEN transport=<pika.adapters.utils.io_services_utils._AsyncPlaintextTransport object at 0x1051c7b60> params=<ConnectionParameters host=localhost port=5672 virtual_host=/ ssl=False>>
2025-07-30 23:54:01,199 - pika.adapters.utils.connection_workflow - INFO - AMQPConnectionWorkflow - reporting success: <SelectConnection OPEN transport=<pika.adapters.utils.io_services_utils._AsyncPlaintextTransport object at 0x1051c7b60> params=<ConnectionParameters host=localhost port=5672 virtual_host=/ ssl=False>>
2025-07-30 23:54:01,199 - pika.adapters.blocking_connection - INFO - Connection workflow succeeded: <SelectConnection OPEN transport=<pika.adapters.utils.io_services_utils._AsyncPlaintextTransport object at 0x1051c7b60> params=<ConnectionParameters host=localhost port=5672 virtual_host=/ ssl=False>>
2025-07-30 23:54:01,199 - pika.adapters.blocking_connection - INFO - Created channel=1
2025-07-30 23:54:01,201 - task_service - INFO - Successfully connected to RabbitMQ
2025-07-30 23:54:01,201 - task_service - INFO - Listening for messages on queue: task_consumer_queue
2025-07-30 23:54:01,201 - task_service - INFO - Press CTRL+C to exit
2025-07-30 23:55:58,912 - task_service - INFO - Starting RabbitMQ consumer thread...
2025-07-30 23:55:58,912 - task_service - INFO - Attempting to connect to RabbitMQ (Attempt 1/3)
2025-07-30 23:55:58,912 - task_service - INFO - RabbitMQ consumer thread started
2025-07-30 23:55:58,913 - __main__ - INFO - ================================================================================
2025-07-30 23:55:58,913 - __main__ - INFO - Starting Task Updater Service at 2025-07-30 23:55:58.913051
2025-07-30 23:55:58,913 - __main__ - INFO - Service Name: Task Updater Service
2025-07-30 23:55:58,913 - __main__ - INFO - Server running on http://localhost:8002
2025-07-30 23:55:58,913 - __main__ - INFO - RabbitMQ consumer is running in the background
2025-07-30 23:55:58,913 - __main__ - INFO - ================================================================================
2025-07-30 23:55:58,916 - pika.adapters.utils.connection_workflow - INFO - Pika version 1.3.2 connecting to ('::1', 5672, 0, 0)
2025-07-30 23:55:58,916 - pika.adapters.utils.io_services_utils - ERROR - Socket failed to connect: <socket.socket fd=12, family=30, type=1, proto=6, laddr=('::1', 52070, 0, 0)>; error=61 (Connection refused)
2025-07-30 23:55:58,916 - pika.adapters.utils.connection_workflow - ERROR - TCP Connection attempt failed: ConnectionRefusedError(61, 'Connection refused'); dest=(<AddressFamily.AF_INET6: 30>, <SocketKind.SOCK_STREAM: 1>, 6, '', ('::1', 5672, 0, 0))
2025-07-30 23:55:58,916 - pika.adapters.utils.connection_workflow - ERROR - AMQPConnector - reporting failure: AMQPConnectorSocketConnectError: ConnectionRefusedError(61, 'Connection refused')
2025-07-30 23:55:58,916 - pika.adapters.utils.connection_workflow - INFO - Pika version 1.3.2 connecting to ('127.0.0.1', 5672)
2025-07-30 23:55:58,917 - pika.adapters.utils.io_services_utils - INFO - Socket connected: <socket.socket fd=12, family=2, type=1, proto=6, laddr=('127.0.0.1', 52071), raddr=('127.0.0.1', 5672)>
2025-07-30 23:55:58,917 - pika.adapters.utils.connection_workflow - INFO - Streaming transport linked up: (<pika.adapters.utils.io_services_utils._AsyncPlaintextTransport object at 0x106f7c050>, _StreamingProtocolShim: <SelectConnection PROTOCOL transport=<pika.adapters.utils.io_services_utils._AsyncPlaintextTransport object at 0x106f7c050> params=<ConnectionParameters host=localhost port=5672 virtual_host=/ ssl=False>>).
2025-07-30 23:55:58,925 - pika.adapters.utils.connection_workflow - INFO - AMQPConnector - reporting success: <SelectConnection OPEN transport=<pika.adapters.utils.io_services_utils._AsyncPlaintextTransport object at 0x106f7c050> params=<ConnectionParameters host=localhost port=5672 virtual_host=/ ssl=False>>
2025-07-30 23:55:58,926 - pika.adapters.utils.connection_workflow - INFO - AMQPConnectionWorkflow - reporting success: <SelectConnection OPEN transport=<pika.adapters.utils.io_services_utils._AsyncPlaintextTransport object at 0x106f7c050> params=<ConnectionParameters host=localhost port=5672 virtual_host=/ ssl=False>>
2025-07-30 23:55:58,926 - pika.adapters.blocking_connection - INFO - Connection workflow succeeded: <SelectConnection OPEN transport=<pika.adapters.utils.io_services_utils._AsyncPlaintextTransport object at 0x106f7c050> params=<ConnectionParameters host=localhost port=5672 virtual_host=/ ssl=False>>
2025-07-30 23:55:58,926 - pika.adapters.blocking_connection - INFO - Created channel=1
2025-07-30 23:55:58,927 - task_service - INFO - Successfully connected to RabbitMQ
2025-07-30 23:55:58,927 - task_service - INFO - Listening for messages on queue: task_consumer_queue
2025-07-30 23:55:58,927 - task_service - INFO - Press CTRL+C to exit
2025-07-30 23:57:23,266 - task_service - INFO - Starting RabbitMQ consumer thread...
2025-07-30 23:57:23,266 - task_service - INFO - Attempting to connect to RabbitMQ (Attempt 1/3)
2025-07-30 23:57:23,266 - task_service - INFO - RabbitMQ consumer thread started
2025-07-30 23:57:23,266 - __main__ - INFO - ================================================================================
2025-07-30 23:57:23,266 - __main__ - INFO - Starting Task Updater Service at 2025-07-30 23:57:23.266632
2025-07-30 23:57:23,266 - __main__ - INFO - Service Name: Task Updater Service
2025-07-30 23:57:23,266 - __main__ - INFO - Server running on http://localhost:8002
2025-07-30 23:57:23,266 - __main__ - INFO - RabbitMQ consumer is running in the background
2025-07-30 23:57:23,266 - __main__ - INFO - ================================================================================
2025-07-30 23:57:23,270 - pika.adapters.utils.connection_workflow - INFO - Pika version 1.3.2 connecting to ('::1', 5672, 0, 0)
2025-07-30 23:57:23,270 - pika.adapters.utils.io_services_utils - ERROR - Socket failed to connect: <socket.socket fd=12, family=30, type=1, proto=6, laddr=('::1', 52199, 0, 0)>; error=61 (Connection refused)
2025-07-30 23:57:23,270 - pika.adapters.utils.connection_workflow - ERROR - TCP Connection attempt failed: ConnectionRefusedError(61, 'Connection refused'); dest=(<AddressFamily.AF_INET6: 30>, <SocketKind.SOCK_STREAM: 1>, 6, '', ('::1', 5672, 0, 0))
2025-07-30 23:57:23,270 - pika.adapters.utils.connection_workflow - ERROR - AMQPConnector - reporting failure: AMQPConnectorSocketConnectError: ConnectionRefusedError(61, 'Connection refused')
2025-07-30 23:57:23,270 - pika.adapters.utils.connection_workflow - INFO - Pika version 1.3.2 connecting to ('127.0.0.1', 5672)
2025-07-30 23:57:23,270 - pika.adapters.utils.io_services_utils - INFO - Socket connected: <socket.socket fd=12, family=2, type=1, proto=6, laddr=('127.0.0.1', 52200), raddr=('127.0.0.1', 5672)>
2025-07-30 23:57:23,270 - pika.adapters.utils.connection_workflow - INFO - Streaming transport linked up: (<pika.adapters.utils.io_services_utils._AsyncPlaintextTransport object at 0x109ec7b60>, _StreamingProtocolShim: <SelectConnection PROTOCOL transport=<pika.adapters.utils.io_services_utils._AsyncPlaintextTransport object at 0x109ec7b60> params=<ConnectionParameters host=localhost port=5672 virtual_host=/ ssl=False>>).
2025-07-30 23:57:23,278 - pika.adapters.utils.connection_workflow - INFO - AMQPConnector - reporting success: <SelectConnection OPEN transport=<pika.adapters.utils.io_services_utils._AsyncPlaintextTransport object at 0x109ec7b60> params=<ConnectionParameters host=localhost port=5672 virtual_host=/ ssl=False>>
2025-07-30 23:57:23,278 - pika.adapters.utils.connection_workflow - INFO - AMQPConnectionWorkflow - reporting success: <SelectConnection OPEN transport=<pika.adapters.utils.io_services_utils._AsyncPlaintextTransport object at 0x109ec7b60> params=<ConnectionParameters host=localhost port=5672 virtual_host=/ ssl=False>>
2025-07-30 23:57:23,278 - pika.adapters.blocking_connection - INFO - Connection workflow succeeded: <SelectConnection OPEN transport=<pika.adapters.utils.io_services_utils._AsyncPlaintextTransport object at 0x109ec7b60> params=<ConnectionParameters host=localhost port=5672 virtual_host=/ ssl=False>>
2025-07-30 23:57:23,279 - pika.adapters.blocking_connection - INFO - Created channel=1
2025-07-30 23:57:23,279 - task_service - INFO - Successfully connected to RabbitMQ
2025-07-30 23:57:23,279 - task_service - INFO - Listening for messages on queue: task_consumer_queue
2025-07-30 23:57:23,279 - task_service - INFO - Press CTRL+C to exit
2025-07-31 00:00:53,005 - task_service - INFO - Starting RabbitMQ consumer thread...
2025-07-31 00:00:53,006 - task_service - INFO - Attempting to connect to RabbitMQ (Attempt 1/3)
2025-07-31 00:00:53,006 - task_service - INFO - RabbitMQ consumer thread started
2025-07-31 00:00:53,007 - __main__ - INFO - ================================================================================
2025-07-31 00:00:53,007 - __main__ - INFO - Starting Task Updater Service at 2025-07-31 00:00:53.007371
2025-07-31 00:00:53,007 - __main__ - INFO - Service Name: Task Updater Service
2025-07-31 00:00:53,007 - __main__ - INFO - Server running on http://localhost:8002
2025-07-31 00:00:53,007 - __main__ - INFO - RabbitMQ consumer is running in the background
2025-07-31 00:00:53,007 - __main__ - INFO - ================================================================================
2025-07-31 00:00:53,019 - pika.adapters.utils.connection_workflow - INFO - Pika version 1.3.2 connecting to ('::1', 5672, 0, 0)
2025-07-31 00:00:53,020 - pika.adapters.utils.io_services_utils - ERROR - Socket failed to connect: <socket.socket fd=12, family=30, type=1, proto=6, laddr=('::1', 52554, 0, 0)>; error=61 (Connection refused)
2025-07-31 00:00:53,020 - pika.adapters.utils.connection_workflow - ERROR - TCP Connection attempt failed: ConnectionRefusedError(61, 'Connection refused'); dest=(<AddressFamily.AF_INET6: 30>, <SocketKind.SOCK_STREAM: 1>, 6, '', ('::1', 5672, 0, 0))
2025-07-31 00:00:53,020 - pika.adapters.utils.connection_workflow - ERROR - AMQPConnector - reporting failure: AMQPConnectorSocketConnectError: ConnectionRefusedError(61, 'Connection refused')
2025-07-31 00:00:53,020 - pika.adapters.utils.connection_workflow - INFO - Pika version 1.3.2 connecting to ('127.0.0.1', 5672)
2025-07-31 00:00:53,020 - pika.adapters.utils.io_services_utils - INFO - Socket connected: <socket.socket fd=12, family=2, type=1, proto=6, laddr=('127.0.0.1', 52555), raddr=('127.0.0.1', 5672)>
2025-07-31 00:00:53,020 - pika.adapters.utils.connection_workflow - INFO - Streaming transport linked up: (<pika.adapters.utils.io_services_utils._AsyncPlaintextTransport object at 0x107fc6510>, _StreamingProtocolShim: <SelectConnection PROTOCOL transport=<pika.adapters.utils.io_services_utils._AsyncPlaintextTransport object at 0x107fc6510> params=<ConnectionParameters host=localhost port=5672 virtual_host=/ ssl=False>>).
2025-07-31 00:00:53,032 - pika.adapters.utils.connection_workflow - INFO - AMQPConnector - reporting success: <SelectConnection OPEN transport=<pika.adapters.utils.io_services_utils._AsyncPlaintextTransport object at 0x107fc6510> params=<ConnectionParameters host=localhost port=5672 virtual_host=/ ssl=False>>
2025-07-31 00:00:53,032 - pika.adapters.utils.connection_workflow - INFO - AMQPConnectionWorkflow - reporting success: <SelectConnection OPEN transport=<pika.adapters.utils.io_services_utils._AsyncPlaintextTransport object at 0x107fc6510> params=<ConnectionParameters host=localhost port=5672 virtual_host=/ ssl=False>>
2025-07-31 00:00:53,032 - pika.adapters.blocking_connection - INFO - Connection workflow succeeded: <SelectConnection OPEN transport=<pika.adapters.utils.io_services_utils._AsyncPlaintextTransport object at 0x107fc6510> params=<ConnectionParameters host=localhost port=5672 virtual_host=/ ssl=False>>
2025-07-31 00:00:53,032 - pika.adapters.blocking_connection - INFO - Created channel=1
2025-07-31 00:00:53,034 - task_service - INFO - Successfully connected to RabbitMQ
2025-07-31 00:00:53,034 - task_service - INFO - Listening for messages on queue: task_consumer_queue
2025-07-31 00:00:53,034 - task_service - INFO - Press CTRL+C to exit
2025-07-31 00:05:32,875 - task_service - INFO - Starting RabbitMQ consumer thread...
2025-07-31 00:05:32,875 - task_service - INFO - Attempting to connect to RabbitMQ (Attempt 1/3)
2025-07-31 00:05:32,875 - task_service - INFO - RabbitMQ consumer thread started
2025-07-31 00:05:32,876 - __main__ - INFO - ================================================================================
2025-07-31 00:05:32,876 - __main__ - INFO - Starting Task Updater Service at 2025-07-31 00:05:32.876407
2025-07-31 00:05:32,876 - __main__ - INFO - Service Name: Task Updater Service
2025-07-31 00:05:32,876 - __main__ - INFO - Server running on http://localhost:8002
2025-07-31 00:08:40,149 - task_service - INFO - Starting RabbitMQ consumer thread...
2025-07-31 00:08:40,149 - task_service - INFO - Attempting to connect to RabbitMQ (Attempt 1/3)
2025-07-31 00:08:40,150 - task_service - INFO - RabbitMQ consumer thread started
2025-07-31 00:08:40,150 - __main__ - INFO - ================================================================================
2025-07-31 00:08:40,150 - __main__ - INFO - Starting Task Updater Service at 2025-07-31 00:08:40.150535
2025-07-31 00:08:40,150 - __main__ - INFO - Service Name: Task Updater Service
2025-07-31 00:08:40,150 - __main__ - INFO - Server running on http://localhost:8002
2025-07-31 00:09:44,230 - task_service - INFO - Starting RabbitMQ consumer thread...
2025-07-31 00:09:44,230 - task_service - INFO - Attempting to connect to RabbitMQ (Attempt 1/3)
2025-07-31 00:09:44,230 - task_service - INFO - RabbitMQ consumer thread started
2025-07-31 00:09:44,231 - __main__ - INFO - ================================================================================
2025-07-31 00:09:44,231 - __main__ - INFO - Starting Task Updater Service at 2025-07-31 00:09:44.231044
2025-07-31 00:09:44,231 - __main__ - INFO - Service Name: Task Updater Service
2025-07-31 00:09:44,231 - __main__ - INFO - Server running on http://localhost:8002
2025-07-31 00:09:44,231 - task_service - INFO - Attempting to connect to RabbitMQ (Attempt 1/3)
2025-07-31 00:09:44,231 - __main__ - INFO - RabbitMQ consumer started in background thread
2025-07-31 00:09:44,231 - __main__ - INFO - ================================================================================
2025-07-31 00:09:44,235 - pika.adapters.utils.connection_workflow - INFO - Pika version 1.3.2 connecting to ('::1', 5672, 0, 0)
2025-07-31 00:09:44,235 - pika.adapters.utils.connection_workflow - INFO - Pika version 1.3.2 connecting to ('::1', 5672, 0, 0)
2025-07-31 00:09:44,235 - pika.adapters.utils.io_services_utils - ERROR - Socket failed to connect: <socket.socket fd=14, family=30, type=1, proto=6, laddr=('::1', 53631, 0, 0)>; error=61 (Connection refused)
2025-07-31 00:09:44,235 - pika.adapters.utils.connection_workflow - ERROR - TCP Connection attempt failed: ConnectionRefusedError(61, 'Connection refused'); dest=(<AddressFamily.AF_INET6: 30>, <SocketKind.SOCK_STREAM: 1>, 6, '', ('::1', 5672, 0, 0))
2025-07-31 00:09:44,235 - pika.adapters.utils.io_services_utils - ERROR - Socket failed to connect: <socket.socket fd=16, family=30, type=1, proto=6, laddr=('::1', 53632, 0, 0)>; error=61 (Connection refused)
2025-07-31 00:09:44,235 - pika.adapters.utils.connection_workflow - ERROR - AMQPConnector - reporting failure: AMQPConnectorSocketConnectError: ConnectionRefusedError(61, 'Connection refused')
2025-07-31 00:09:44,235 - pika.adapters.utils.connection_workflow - ERROR - TCP Connection attempt failed: ConnectionRefusedError(61, 'Connection refused'); dest=(<AddressFamily.AF_INET6: 30>, <SocketKind.SOCK_STREAM: 1>, 6, '', ('::1', 5672, 0, 0))
2025-07-31 00:09:44,236 - pika.adapters.utils.connection_workflow - INFO - Pika version 1.3.2 connecting to ('127.0.0.1', 5672)
2025-07-31 00:09:44,236 - pika.adapters.utils.connection_workflow - ERROR - AMQPConnector - reporting failure: AMQPConnectorSocketConnectError: ConnectionRefusedError(61, 'Connection refused')
2025-07-31 00:09:44,236 - pika.adapters.utils.connection_workflow - INFO - Pika version 1.3.2 connecting to ('127.0.0.1', 5672)
2025-07-31 00:09:44,236 - pika.adapters.utils.io_services_utils - INFO - Socket connected: <socket.socket fd=12, family=2, type=1, proto=6, laddr=('127.0.0.1', 53633), raddr=('127.0.0.1', 5672)>
2025-07-31 00:09:44,236 - pika.adapters.utils.io_services_utils - INFO - Socket connected: <socket.socket fd=16, family=2, type=1, proto=6, laddr=('127.0.0.1', 53634), raddr=('127.0.0.1', 5672)>
2025-07-31 00:09:44,236 - pika.adapters.utils.connection_workflow - INFO - Streaming transport linked up: (<pika.adapters.utils.io_services_utils._AsyncPlaintextTransport object at 0x1075c7e00>, _StreamingProtocolShim: <SelectConnection PROTOCOL transport=<pika.adapters.utils.io_services_utils._AsyncPlaintextTransport object at 0x1075c7e00> params=<ConnectionParameters host=localhost port=5672 virtual_host=/ ssl=False>>).
2025-07-31 00:09:44,236 - pika.adapters.utils.connection_workflow - INFO - Streaming transport linked up: (<pika.adapters.utils.io_services_utils._AsyncPlaintextTransport object at 0x10761f110>, _StreamingProtocolShim: <SelectConnection PROTOCOL transport=<pika.adapters.utils.io_services_utils._AsyncPlaintextTransport object at 0x10761f110> params=<ConnectionParameters host=localhost port=5672 virtual_host=/ ssl=False>>).
2025-07-31 00:09:44,253 - pika.adapters.utils.connection_workflow - INFO - AMQPConnector - reporting success: <SelectConnection OPEN transport=<pika.adapters.utils.io_services_utils._AsyncPlaintextTransport object at 0x1075c7e00> params=<ConnectionParameters host=localhost port=5672 virtual_host=/ ssl=False>>
2025-07-31 00:09:44,253 - pika.adapters.utils.connection_workflow - INFO - AMQPConnectionWorkflow - reporting success: <SelectConnection OPEN transport=<pika.adapters.utils.io_services_utils._AsyncPlaintextTransport object at 0x1075c7e00> params=<ConnectionParameters host=localhost port=5672 virtual_host=/ ssl=False>>
2025-07-31 00:09:44,253 - pika.adapters.blocking_connection - INFO - Connection workflow succeeded: <SelectConnection OPEN transport=<pika.adapters.utils.io_services_utils._AsyncPlaintextTransport object at 0x1075c7e00> params=<ConnectionParameters host=localhost port=5672 virtual_host=/ ssl=False>>
2025-07-31 00:09:44,254 - pika.adapters.utils.connection_workflow - INFO - AMQPConnector - reporting success: <SelectConnection OPEN transport=<pika.adapters.utils.io_services_utils._AsyncPlaintextTransport object at 0x10761f110> params=<ConnectionParameters host=localhost port=5672 virtual_host=/ ssl=False>>
2025-07-31 00:09:44,254 - pika.adapters.blocking_connection - INFO - Created channel=1
2025-07-31 00:09:44,254 - pika.adapters.utils.connection_workflow - INFO - AMQPConnectionWorkflow - reporting success: <SelectConnection OPEN transport=<pika.adapters.utils.io_services_utils._AsyncPlaintextTransport object at 0x10761f110> params=<ConnectionParameters host=localhost port=5672 virtual_host=/ ssl=False>>
2025-07-31 00:09:44,254 - pika.adapters.blocking_connection - INFO - Connection workflow succeeded: <SelectConnection OPEN transport=<pika.adapters.utils.io_services_utils._AsyncPlaintextTransport object at 0x10761f110> params=<ConnectionParameters host=localhost port=5672 virtual_host=/ ssl=False>>
2025-07-31 00:09:44,254 - pika.adapters.blocking_connection - INFO - Created channel=1
2025-07-31 00:09:44,256 - task_service - INFO - Successfully connected to RabbitMQ
2025-07-31 00:09:44,256 - task_service - INFO - Successfully connected to RabbitMQ
2025-07-31 00:09:44,256 - task_service - INFO - Listening for messages on queue: task_consumer_queue
2025-07-31 00:09:44,256 - task_service - INFO - Listening for messages on queue: task_consumer_queue
2025-07-31 00:09:44,256 - task_service - INFO - Press CTRL+C to exit
2025-07-31 00:09:44,256 - task_service - INFO - Press CTRL+C to exit
2025-07-31 00:10:53,955 - __main__ - INFO - ================================================================================
2025-07-31 00:10:53,955 - __main__ - INFO - Starting Task Updater Service at 2025-07-31 00:10:53.955285
2025-07-31 00:10:53,955 - __main__ - INFO - Service Name: Task Updater Service
2025-07-31 00:10:53,955 - __main__ - INFO - Server running on http://localhost:8002
2025-07-31 00:10:53,955 - task_service - INFO - Attempting to connect to RabbitMQ (Attempt 1/3)
2025-07-31 00:10:53,955 - __main__ - INFO - RabbitMQ consumer started in background thread
2025-07-31 00:10:53,955 - __main__ - INFO - ================================================================================
2025-07-31 00:10:53,959 - pika.adapters.utils.connection_workflow - INFO - Pika version 1.3.2 connecting to ('::1', 5672, 0, 0)
2025-07-31 00:10:53,959 - pika.adapters.utils.io_services_utils - ERROR - Socket failed to connect: <socket.socket fd=12, family=30, type=1, proto=6, laddr=('::1', 53743, 0, 0)>; error=61 (Connection refused)
2025-07-31 00:10:53,959 - pika.adapters.utils.connection_workflow - ERROR - TCP Connection attempt failed: ConnectionRefusedError(61, 'Connection refused'); dest=(<AddressFamily.AF_INET6: 30>, <SocketKind.SOCK_STREAM: 1>, 6, '', ('::1', 5672, 0, 0))
2025-07-31 00:10:53,959 - pika.adapters.utils.connection_workflow - ERROR - AMQPConnector - reporting failure: AMQPConnectorSocketConnectError: ConnectionRefusedError(61, 'Connection refused')
2025-07-31 00:10:53,959 - pika.adapters.utils.connection_workflow - INFO - Pika version 1.3.2 connecting to ('127.0.0.1', 5672)
2025-07-31 00:10:53,959 - pika.adapters.utils.io_services_utils - INFO - Socket connected: <socket.socket fd=12, family=2, type=1, proto=6, laddr=('127.0.0.1', 53744), raddr=('127.0.0.1', 5672)>
2025-07-31 00:10:53,959 - pika.adapters.utils.connection_workflow - INFO - Streaming transport linked up: (<pika.adapters.utils.io_services_utils._AsyncPlaintextTransport object at 0x1033dbb60>, _StreamingProtocolShim: <SelectConnection PROTOCOL transport=<pika.adapters.utils.io_services_utils._AsyncPlaintextTransport object at 0x1033dbb60> params=<ConnectionParameters host=localhost port=5672 virtual_host=/ ssl=False>>).
2025-07-31 00:10:53,968 - pika.adapters.utils.connection_workflow - INFO - AMQPConnector - reporting success: <SelectConnection OPEN transport=<pika.adapters.utils.io_services_utils._AsyncPlaintextTransport object at 0x1033dbb60> params=<ConnectionParameters host=localhost port=5672 virtual_host=/ ssl=False>>
2025-07-31 00:10:53,968 - pika.adapters.utils.connection_workflow - INFO - AMQPConnectionWorkflow - reporting success: <SelectConnection OPEN transport=<pika.adapters.utils.io_services_utils._AsyncPlaintextTransport object at 0x1033dbb60> params=<ConnectionParameters host=localhost port=5672 virtual_host=/ ssl=False>>
2025-07-31 00:10:53,968 - pika.adapters.blocking_connection - INFO - Connection workflow succeeded: <SelectConnection OPEN transport=<pika.adapters.utils.io_services_utils._AsyncPlaintextTransport object at 0x1033dbb60> params=<ConnectionParameters host=localhost port=5672 virtual_host=/ ssl=False>>
2025-07-31 00:10:53,968 - pika.adapters.blocking_connection - INFO - Created channel=1
2025-07-31 00:10:53,970 - task_service - INFO - Successfully connected to RabbitMQ
2025-07-31 00:10:53,970 - task_service - INFO - Listening for messages on queue: task_consumer_queue
2025-07-31 00:10:53,970 - task_service - INFO - Press CTRL+C to exit
2025-07-31 00:11:42,721 - task_service - INFO - Processing message - Task ID: 392da3f4-f891-4ea0-b30d-a5171a743288, Action: create
2025-07-31 00:11:42,721 - task_service - INFO - Creating/Updating task - ID: 392da3f4-f891-4ea0-b30d-a5171a743288
2025-07-31 00:11:42,721 - task_service - INFO - Task Name: hola 
2025-07-31 00:11:42,722 - task_service - INFO - Description: me lalamo
2025-07-31 00:11:42,722 - task_service - INFO - Assignee: martin
2025-07-31 00:11:42,722 - task_service - INFO - Successfully processed message for task ID: 392da3f4-f891-4ea0-b30d-a5171a743288
2025-07-31 21:42:16,789 - __main__ - INFO - ================================================================================
2025-07-31 21:42:16,789 - __main__ - INFO - Starting Task Updater Service at 2025-07-31 21:42:16.789940
2025-07-31 21:42:16,789 - __main__ - INFO - Service Name: Task Updater Service
2025-07-31 21:42:16,790 - __main__ - INFO - Server running on http://localhost:8002
2025-07-31 21:42:16,790 - task_service - INFO - Attempting to connect to RabbitMQ (Attempt 1/3)
2025-07-31 21:42:16,790 - __main__ - INFO - RabbitMQ consumer started in background thread
2025-07-31 21:42:16,790 - __main__ - INFO - ================================================================================
2025-07-31 21:42:16,796 - pika.adapters.utils.connection_workflow - INFO - Pika version 1.3.2 connecting to ('::1', 5672, 0, 0)
2025-07-31 21:42:16,796 - pika.adapters.utils.io_services_utils - ERROR - Socket failed to connect: <socket.socket fd=12, family=30, type=1, proto=6, laddr=('::1', 60355, 0, 0)>; error=61 (Connection refused)
2025-07-31 21:42:16,796 - pika.adapters.utils.connection_workflow - ERROR - TCP Connection attempt failed: ConnectionRefusedError(61, 'Connection refused'); dest=(<AddressFamily.AF_INET6: 30>, <SocketKind.SOCK_STREAM: 1>, 6, '', ('::1', 5672, 0, 0))
2025-07-31 21:42:16,796 - pika.adapters.utils.connection_workflow - ERROR - AMQPConnector - reporting failure: AMQPConnectorSocketConnectError: ConnectionRefusedError(61, 'Connection refused')
2025-07-31 21:42:16,796 - pika.adapters.utils.connection_workflow - INFO - Pika version 1.3.2 connecting to ('127.0.0.1', 5672)
2025-07-31 21:42:16,797 - pika.adapters.utils.io_services_utils - INFO - Socket connected: <socket.socket fd=12, family=2, type=1, proto=6, laddr=('127.0.0.1', 60356), raddr=('127.0.0.1', 5672)>
2025-07-31 21:42:16,797 - pika.adapters.utils.connection_workflow - INFO - Streaming transport linked up: (<pika.adapters.utils.io_services_utils._AsyncPlaintextTransport object at 0x1077742f0>, _StreamingProtocolShim: <SelectConnection PROTOCOL transport=<pika.adapters.utils.io_services_utils._AsyncPlaintextTransport object at 0x1077742f0> params=<ConnectionParameters host=localhost port=5672 virtual_host=/ ssl=False>>).
2025-07-31 21:42:16,808 - pika.adapters.utils.connection_workflow - INFO - AMQPConnector - reporting success: <SelectConnection OPEN transport=<pika.adapters.utils.io_services_utils._AsyncPlaintextTransport object at 0x1077742f0> params=<ConnectionParameters host=localhost port=5672 virtual_host=/ ssl=False>>
2025-07-31 21:42:16,808 - pika.adapters.utils.connection_workflow - INFO - AMQPConnectionWorkflow - reporting success: <SelectConnection OPEN transport=<pika.adapters.utils.io_services_utils._AsyncPlaintextTransport object at 0x1077742f0> params=<ConnectionParameters host=localhost port=5672 virtual_host=/ ssl=False>>
2025-07-31 21:42:16,808 - pika.adapters.blocking_connection - INFO - Connection workflow succeeded: <SelectConnection OPEN transport=<pika.adapters.utils.io_services_utils._AsyncPlaintextTransport object at 0x1077742f0> params=<ConnectionParameters host=localhost port=5672 virtual_host=/ ssl=False>>
2025-07-31 21:42:16,808 - pika.adapters.blocking_connection - INFO - Created channel=1
2025-07-31 21:42:16,811 - task_service - INFO - Successfully connected to RabbitMQ
2025-07-31 21:42:16,811 - task_service - INFO - Listening for messages on queue: task_consumer_queue
2025-07-31 21:42:16,811 - task_service - INFO - Press CTRL+C to exit
2025-07-31 21:44:03,687 - __main__ - INFO - ================================================================================
2025-07-31 21:44:03,687 - __main__ - INFO - Starting Task Updater Service at 2025-07-31 21:44:03.687768
2025-07-31 21:44:03,687 - __main__ - INFO - Service Name: Task Updater Service
2025-07-31 21:44:03,687 - __main__ - INFO - Server running on http://localhost:8002
2025-07-31 21:44:03,687 - task_service - INFO - Attempting to connect to RabbitMQ (Attempt 1/3)
2025-07-31 21:44:03,687 - __main__ - INFO - RabbitMQ consumer started in background thread
2025-07-31 21:44:03,688 - __main__ - INFO - ================================================================================
2025-07-31 21:44:03,692 - pika.adapters.utils.connection_workflow - INFO - Pika version 1.3.2 connecting to ('::1', 5672, 0, 0)
2025-07-31 21:44:03,692 - pika.adapters.utils.io_services_utils - ERROR - Socket failed to connect: <socket.socket fd=12, family=30, type=1, proto=6, laddr=('::1', 60468, 0, 0)>; error=61 (Connection refused)
2025-07-31 21:44:03,692 - pika.adapters.utils.connection_workflow - ERROR - TCP Connection attempt failed: ConnectionRefusedError(61, 'Connection refused'); dest=(<AddressFamily.AF_INET6: 30>, <SocketKind.SOCK_STREAM: 1>, 6, '', ('::1', 5672, 0, 0))
2025-07-31 21:44:03,692 - pika.adapters.utils.connection_workflow - ERROR - AMQPConnector - reporting failure: AMQPConnectorSocketConnectError: ConnectionRefusedError(61, 'Connection refused')
2025-07-31 21:44:03,692 - pika.adapters.utils.connection_workflow - INFO - Pika version 1.3.2 connecting to ('127.0.0.1', 5672)
2025-07-31 21:44:03,692 - pika.adapters.utils.io_services_utils - INFO - Socket connected: <socket.socket fd=12, family=2, type=1, proto=6, laddr=('127.0.0.1', 60469), raddr=('127.0.0.1', 5672)>
2025-07-31 21:44:03,693 - pika.adapters.utils.connection_workflow - INFO - Streaming transport linked up: (<pika.adapters.utils.io_services_utils._AsyncPlaintextTransport object at 0x104c98050>, _StreamingProtocolShim: <SelectConnection PROTOCOL transport=<pika.adapters.utils.io_services_utils._AsyncPlaintextTransport object at 0x104c98050> params=<ConnectionParameters host=localhost port=5672 virtual_host=/ ssl=False>>).
2025-07-31 21:44:03,701 - pika.adapters.utils.connection_workflow - INFO - AMQPConnector - reporting success: <SelectConnection OPEN transport=<pika.adapters.utils.io_services_utils._AsyncPlaintextTransport object at 0x104c98050> params=<ConnectionParameters host=localhost port=5672 virtual_host=/ ssl=False>>
2025-07-31 21:44:03,701 - pika.adapters.utils.connection_workflow - INFO - AMQPConnectionWorkflow - reporting success: <SelectConnection OPEN transport=<pika.adapters.utils.io_services_utils._AsyncPlaintextTransport object at 0x104c98050> params=<ConnectionParameters host=localhost port=5672 virtual_host=/ ssl=False>>
2025-07-31 21:44:03,702 - pika.adapters.blocking_connection - INFO - Connection workflow succeeded: <SelectConnection OPEN transport=<pika.adapters.utils.io_services_utils._AsyncPlaintextTransport object at 0x104c98050> params=<ConnectionParameters host=localhost port=5672 virtual_host=/ ssl=False>>
2025-07-31 21:44:03,702 - pika.adapters.blocking_connection - INFO - Created channel=1
2025-07-31 21:44:03,703 - task_service - INFO - Successfully connected to RabbitMQ
2025-07-31 21:44:03,703 - task_service - INFO - Listening for messages on queue: task_consumer_queue
2025-07-31 21:44:03,703 - task_service - INFO - Press CTRL+C to exit
2025-07-31 21:44:20,710 - task_service - INFO - Processing message - Task ID: c972d1ac-c444-4ad7-90a9-30d3c4be217c, Action: create
2025-07-31 21:44:20,710 - task_service - INFO - Creating/Updating task - ID: c972d1ac-c444-4ad7-90a9-30d3c4be217c
2025-07-31 21:44:20,710 - task_service - INFO - Task Name: asdf
2025-07-31 21:44:20,710 - task_service - INFO - Description: asdf
2025-07-31 21:44:20,710 - task_service - INFO - Assignee: sdf
2025-07-31 21:44:20,710 - task_service - INFO - Successfully processed message for task ID: c972d1ac-c444-4ad7-90a9-30d3c4be217c
2025-07-31 21:54:58,255 - __main__ - INFO - ================================================================================
2025-07-31 21:54:58,255 - __main__ - INFO - Starting Task Updater Service at 2025-07-31 21:54:58.255464
2025-07-31 21:54:58,255 - __main__ - INFO - Service Name: Task Updater Service
2025-07-31 21:54:58,255 - __main__ - INFO - Server running on http://localhost:8002
2025-07-31 21:54:58,255 - task_service - INFO - Attempting to connect to SQS (Attempt 1/3)
2025-07-31 21:54:58,255 - __main__ - INFO - RabbitMQ consumer started in background thread
2025-07-31 21:54:58,258 - __main__ - INFO - ================================================================================
2025-07-31 21:54:58,316 - task_service - ERROR - Error in SQS consumer: Unable to locate credentials
Traceback (most recent call last):
  File "/Users/martinlequerica/Documents/workspace/examen_qa/task_logger/task_service.py", line 128, in start_consumer
    queue_url = get_queue_url(sqs_client)
  File "/Users/martinlequerica/Documents/workspace/examen_qa/task_logger/task_service.py", line 107, in get_queue_url
    response = sqs_client.get_queue_url(QueueName=CONFIG['sqs']['queue_name'])
  File "/Users/martinlequerica/Documents/workspace/examen_qa/venv/lib/python3.13/site-packages/botocore/client.py", line 601, in _api_call
    return self._make_api_call(operation_name, kwargs)
           ~~~~~~~~~~~~~~~~~~~^^^^^^^^^^^^^^^^^^^^^^^^
  File "/Users/martinlequerica/Documents/workspace/examen_qa/venv/lib/python3.13/site-packages/botocore/context.py", line 123, in wrapper
    return func(*args, **kwargs)
  File "/Users/martinlequerica/Documents/workspace/examen_qa/venv/lib/python3.13/site-packages/botocore/client.py", line 1056, in _make_api_call
    http, parsed_response = self._make_request(
                            ~~~~~~~~~~~~~~~~~~^
        operation_model, request_dict, request_context
        ^^^^^^^^^^^^^^^^^^^^^^^^^^^^^^^^^^^^^^^^^^^^^^
    )
    ^
  File "/Users/martinlequerica/Documents/workspace/examen_qa/venv/lib/python3.13/site-packages/botocore/client.py", line 1080, in _make_request
    return self._endpoint.make_request(operation_model, request_dict)
           ~~~~~~~~~~~~~~~~~~~~~~~~~~~^^^^^^^^^^^^^^^^^^^^^^^^^^^^^^^
  File "/Users/martinlequerica/Documents/workspace/examen_qa/venv/lib/python3.13/site-packages/botocore/endpoint.py", line 118, in make_request
    return self._send_request(request_dict, operation_model)
           ~~~~~~~~~~~~~~~~~~^^^^^^^^^^^^^^^^^^^^^^^^^^^^^^^
  File "/Users/martinlequerica/Documents/workspace/examen_qa/venv/lib/python3.13/site-packages/botocore/endpoint.py", line 195, in _send_request
    request = self.create_request(request_dict, operation_model)
  File "/Users/martinlequerica/Documents/workspace/examen_qa/venv/lib/python3.13/site-packages/botocore/endpoint.py", line 131, in create_request
    self._event_emitter.emit(
    ~~~~~~~~~~~~~~~~~~~~~~~~^
        event_name,
        ^^^^^^^^^^^
        request=request,
        ^^^^^^^^^^^^^^^^
        operation_name=operation_model.name,
        ^^^^^^^^^^^^^^^^^^^^^^^^^^^^^^^^^^^^
    )
    ^
  File "/Users/martinlequerica/Documents/workspace/examen_qa/venv/lib/python3.13/site-packages/botocore/hooks.py", line 412, in emit
    return self._emitter.emit(aliased_event_name, **kwargs)
           ~~~~~~~~~~~~~~~~~~^^^^^^^^^^^^^^^^^^^^^^^^^^^^^^
  File "/Users/martinlequerica/Documents/workspace/examen_qa/venv/lib/python3.13/site-packages/botocore/hooks.py", line 256, in emit
    return self._emit(event_name, kwargs)
           ~~~~~~~~~~^^^^^^^^^^^^^^^^^^^^
  File "/Users/martinlequerica/Documents/workspace/examen_qa/venv/lib/python3.13/site-packages/botocore/hooks.py", line 239, in _emit
    response = handler(**kwargs)
  File "/Users/martinlequerica/Documents/workspace/examen_qa/venv/lib/python3.13/site-packages/botocore/signers.py", line 108, in handler
    return self.sign(operation_name, request)
           ~~~~~~~~~^^^^^^^^^^^^^^^^^^^^^^^^^
  File "/Users/martinlequerica/Documents/workspace/examen_qa/venv/lib/python3.13/site-packages/botocore/signers.py", line 200, in sign
    auth.add_auth(request)
    ~~~~~~~~~~~~~^^^^^^^^^
  File "/Users/martinlequerica/Documents/workspace/examen_qa/venv/lib/python3.13/site-packages/botocore/auth.py", line 421, in add_auth
    raise NoCredentialsError()
botocore.exceptions.NoCredentialsError: Unable to locate credentials
2025-07-31 21:54:58,320 - task_service - WARNING - Connection attempt 1 failed. Retrying in 5 seconds...
2025-07-31 21:55:03,321 - task_service - INFO - Disconnected from SQS
2025-07-31 21:55:03,321 - task_service - INFO - Attempting to connect to SQS (Attempt 2/3)
2025-07-31 21:55:03,329 - task_service - ERROR - Error in SQS consumer: Unable to locate credentials
Traceback (most recent call last):
  File "/Users/martinlequerica/Documents/workspace/examen_qa/task_logger/task_service.py", line 128, in start_consumer
    queue_url = get_queue_url(sqs_client)
  File "/Users/martinlequerica/Documents/workspace/examen_qa/task_logger/task_service.py", line 107, in get_queue_url
    response = sqs_client.get_queue_url(QueueName=CONFIG['sqs']['queue_name'])
  File "/Users/martinlequerica/Documents/workspace/examen_qa/venv/lib/python3.13/site-packages/botocore/client.py", line 601, in _api_call
    return self._make_api_call(operation_name, kwargs)
           ~~~~~~~~~~~~~~~~~~~^^^^^^^^^^^^^^^^^^^^^^^^
  File "/Users/martinlequerica/Documents/workspace/examen_qa/venv/lib/python3.13/site-packages/botocore/context.py", line 123, in wrapper
    return func(*args, **kwargs)
  File "/Users/martinlequerica/Documents/workspace/examen_qa/venv/lib/python3.13/site-packages/botocore/client.py", line 1056, in _make_api_call
    http, parsed_response = self._make_request(
                            ~~~~~~~~~~~~~~~~~~^
        operation_model, request_dict, request_context
        ^^^^^^^^^^^^^^^^^^^^^^^^^^^^^^^^^^^^^^^^^^^^^^
    )
    ^
  File "/Users/martinlequerica/Documents/workspace/examen_qa/venv/lib/python3.13/site-packages/botocore/client.py", line 1080, in _make_request
    return self._endpoint.make_request(operation_model, request_dict)
           ~~~~~~~~~~~~~~~~~~~~~~~~~~~^^^^^^^^^^^^^^^^^^^^^^^^^^^^^^^
  File "/Users/martinlequerica/Documents/workspace/examen_qa/venv/lib/python3.13/site-packages/botocore/endpoint.py", line 118, in make_request
    return self._send_request(request_dict, operation_model)
           ~~~~~~~~~~~~~~~~~~^^^^^^^^^^^^^^^^^^^^^^^^^^^^^^^
  File "/Users/martinlequerica/Documents/workspace/examen_qa/venv/lib/python3.13/site-packages/botocore/endpoint.py", line 195, in _send_request
    request = self.create_request(request_dict, operation_model)
  File "/Users/martinlequerica/Documents/workspace/examen_qa/venv/lib/python3.13/site-packages/botocore/endpoint.py", line 131, in create_request
    self._event_emitter.emit(
    ~~~~~~~~~~~~~~~~~~~~~~~~^
        event_name,
        ^^^^^^^^^^^
        request=request,
        ^^^^^^^^^^^^^^^^
        operation_name=operation_model.name,
        ^^^^^^^^^^^^^^^^^^^^^^^^^^^^^^^^^^^^
    )
    ^
  File "/Users/martinlequerica/Documents/workspace/examen_qa/venv/lib/python3.13/site-packages/botocore/hooks.py", line 412, in emit
    return self._emitter.emit(aliased_event_name, **kwargs)
           ~~~~~~~~~~~~~~~~~~^^^^^^^^^^^^^^^^^^^^^^^^^^^^^^
  File "/Users/martinlequerica/Documents/workspace/examen_qa/venv/lib/python3.13/site-packages/botocore/hooks.py", line 256, in emit
    return self._emit(event_name, kwargs)
           ~~~~~~~~~~^^^^^^^^^^^^^^^^^^^^
  File "/Users/martinlequerica/Documents/workspace/examen_qa/venv/lib/python3.13/site-packages/botocore/hooks.py", line 239, in _emit
    response = handler(**kwargs)
  File "/Users/martinlequerica/Documents/workspace/examen_qa/venv/lib/python3.13/site-packages/botocore/signers.py", line 108, in handler
    return self.sign(operation_name, request)
           ~~~~~~~~~^^^^^^^^^^^^^^^^^^^^^^^^^
  File "/Users/martinlequerica/Documents/workspace/examen_qa/venv/lib/python3.13/site-packages/botocore/signers.py", line 200, in sign
    auth.add_auth(request)
    ~~~~~~~~~~~~~^^^^^^^^^
  File "/Users/martinlequerica/Documents/workspace/examen_qa/venv/lib/python3.13/site-packages/botocore/auth.py", line 421, in add_auth
    raise NoCredentialsError()
botocore.exceptions.NoCredentialsError: Unable to locate credentials
2025-07-31 21:55:03,331 - task_service - WARNING - Connection attempt 2 failed. Retrying in 5 seconds...
2025-07-31 21:59:17,801 - __main__ - INFO - ================================================================================
2025-07-31 21:59:17,801 - __main__ - INFO - Starting Task Updater Service at 2025-07-31 21:59:17.801591
2025-07-31 21:59:17,801 - __main__ - INFO - Service Name: Task Updater Service
2025-07-31 21:59:17,801 - __main__ - INFO - Server running on http://localhost:8002
2025-07-31 21:59:17,801 - task_service - INFO - Attempting to connect to SQS (Attempt 1/3)
2025-07-31 21:59:17,804 - __main__ - INFO - RabbitMQ consumer started in background thread
2025-07-31 21:59:17,805 - __main__ - INFO - ================================================================================
2025-07-31 21:59:19,859 - task_service - ERROR - Error in SQS consumer: Unable to locate credentials
Traceback (most recent call last):
  File "/Users/martinlequerica/Documents/workspace/examen_qa/task_logger/task_service.py", line 128, in start_consumer
    queue_url = get_queue_url(sqs_client)
  File "/Users/martinlequerica/Documents/workspace/examen_qa/task_logger/task_service.py", line 107, in get_queue_url
    response = sqs_client.get_queue_url(QueueName=CONFIG['sqs']['queue_name'])
  File "/Users/martinlequerica/Documents/workspace/examen_qa/venv/lib/python3.13/site-packages/botocore/client.py", line 601, in _api_call
    return self._make_api_call(operation_name, kwargs)
           ~~~~~~~~~~~~~~~~~~~^^^^^^^^^^^^^^^^^^^^^^^^
  File "/Users/martinlequerica/Documents/workspace/examen_qa/venv/lib/python3.13/site-packages/botocore/context.py", line 123, in wrapper
    return func(*args, **kwargs)
  File "/Users/martinlequerica/Documents/workspace/examen_qa/venv/lib/python3.13/site-packages/botocore/client.py", line 1056, in _make_api_call
    http, parsed_response = self._make_request(
                            ~~~~~~~~~~~~~~~~~~^
        operation_model, request_dict, request_context
        ^^^^^^^^^^^^^^^^^^^^^^^^^^^^^^^^^^^^^^^^^^^^^^
    )
    ^
  File "/Users/martinlequerica/Documents/workspace/examen_qa/venv/lib/python3.13/site-packages/botocore/client.py", line 1080, in _make_request
    return self._endpoint.make_request(operation_model, request_dict)
           ~~~~~~~~~~~~~~~~~~~~~~~~~~~^^^^^^^^^^^^^^^^^^^^^^^^^^^^^^^
  File "/Users/martinlequerica/Documents/workspace/examen_qa/venv/lib/python3.13/site-packages/botocore/endpoint.py", line 118, in make_request
    return self._send_request(request_dict, operation_model)
           ~~~~~~~~~~~~~~~~~~^^^^^^^^^^^^^^^^^^^^^^^^^^^^^^^
  File "/Users/martinlequerica/Documents/workspace/examen_qa/venv/lib/python3.13/site-packages/botocore/endpoint.py", line 195, in _send_request
    request = self.create_request(request_dict, operation_model)
  File "/Users/martinlequerica/Documents/workspace/examen_qa/venv/lib/python3.13/site-packages/botocore/endpoint.py", line 131, in create_request
    self._event_emitter.emit(
    ~~~~~~~~~~~~~~~~~~~~~~~~^
        event_name,
        ^^^^^^^^^^^
        request=request,
        ^^^^^^^^^^^^^^^^
        operation_name=operation_model.name,
        ^^^^^^^^^^^^^^^^^^^^^^^^^^^^^^^^^^^^
    )
    ^
  File "/Users/martinlequerica/Documents/workspace/examen_qa/venv/lib/python3.13/site-packages/botocore/hooks.py", line 412, in emit
    return self._emitter.emit(aliased_event_name, **kwargs)
           ~~~~~~~~~~~~~~~~~~^^^^^^^^^^^^^^^^^^^^^^^^^^^^^^
  File "/Users/martinlequerica/Documents/workspace/examen_qa/venv/lib/python3.13/site-packages/botocore/hooks.py", line 256, in emit
    return self._emit(event_name, kwargs)
           ~~~~~~~~~~^^^^^^^^^^^^^^^^^^^^
  File "/Users/martinlequerica/Documents/workspace/examen_qa/venv/lib/python3.13/site-packages/botocore/hooks.py", line 239, in _emit
    response = handler(**kwargs)
  File "/Users/martinlequerica/Documents/workspace/examen_qa/venv/lib/python3.13/site-packages/botocore/signers.py", line 108, in handler
    return self.sign(operation_name, request)
           ~~~~~~~~~^^^^^^^^^^^^^^^^^^^^^^^^^
  File "/Users/martinlequerica/Documents/workspace/examen_qa/venv/lib/python3.13/site-packages/botocore/signers.py", line 200, in sign
    auth.add_auth(request)
    ~~~~~~~~~~~~~^^^^^^^^^
  File "/Users/martinlequerica/Documents/workspace/examen_qa/venv/lib/python3.13/site-packages/botocore/auth.py", line 421, in add_auth
    raise NoCredentialsError()
botocore.exceptions.NoCredentialsError: Unable to locate credentials
2025-07-31 21:59:19,863 - task_service - WARNING - Connection attempt 1 failed. Retrying in 5 seconds...
2025-07-31 21:59:24,865 - task_service - INFO - Disconnected from SQS
2025-07-31 21:59:24,866 - task_service - INFO - Attempting to connect to SQS (Attempt 2/3)
2025-07-31 21:59:24,875 - task_service - ERROR - Error in SQS consumer: Unable to locate credentials
Traceback (most recent call last):
  File "/Users/martinlequerica/Documents/workspace/examen_qa/task_logger/task_service.py", line 128, in start_consumer
    queue_url = get_queue_url(sqs_client)
  File "/Users/martinlequerica/Documents/workspace/examen_qa/task_logger/task_service.py", line 107, in get_queue_url
    response = sqs_client.get_queue_url(QueueName=CONFIG['sqs']['queue_name'])
  File "/Users/martinlequerica/Documents/workspace/examen_qa/venv/lib/python3.13/site-packages/botocore/client.py", line 601, in _api_call
    return self._make_api_call(operation_name, kwargs)
           ~~~~~~~~~~~~~~~~~~~^^^^^^^^^^^^^^^^^^^^^^^^
  File "/Users/martinlequerica/Documents/workspace/examen_qa/venv/lib/python3.13/site-packages/botocore/context.py", line 123, in wrapper
    return func(*args, **kwargs)
  File "/Users/martinlequerica/Documents/workspace/examen_qa/venv/lib/python3.13/site-packages/botocore/client.py", line 1056, in _make_api_call
    http, parsed_response = self._make_request(
                            ~~~~~~~~~~~~~~~~~~^
        operation_model, request_dict, request_context
        ^^^^^^^^^^^^^^^^^^^^^^^^^^^^^^^^^^^^^^^^^^^^^^
    )
    ^
  File "/Users/martinlequerica/Documents/workspace/examen_qa/venv/lib/python3.13/site-packages/botocore/client.py", line 1080, in _make_request
    return self._endpoint.make_request(operation_model, request_dict)
           ~~~~~~~~~~~~~~~~~~~~~~~~~~~^^^^^^^^^^^^^^^^^^^^^^^^^^^^^^^
  File "/Users/martinlequerica/Documents/workspace/examen_qa/venv/lib/python3.13/site-packages/botocore/endpoint.py", line 118, in make_request
    return self._send_request(request_dict, operation_model)
           ~~~~~~~~~~~~~~~~~~^^^^^^^^^^^^^^^^^^^^^^^^^^^^^^^
  File "/Users/martinlequerica/Documents/workspace/examen_qa/venv/lib/python3.13/site-packages/botocore/endpoint.py", line 195, in _send_request
    request = self.create_request(request_dict, operation_model)
  File "/Users/martinlequerica/Documents/workspace/examen_qa/venv/lib/python3.13/site-packages/botocore/endpoint.py", line 131, in create_request
    self._event_emitter.emit(
    ~~~~~~~~~~~~~~~~~~~~~~~~^
        event_name,
        ^^^^^^^^^^^
        request=request,
        ^^^^^^^^^^^^^^^^
        operation_name=operation_model.name,
        ^^^^^^^^^^^^^^^^^^^^^^^^^^^^^^^^^^^^
    )
    ^
  File "/Users/martinlequerica/Documents/workspace/examen_qa/venv/lib/python3.13/site-packages/botocore/hooks.py", line 412, in emit
    return self._emitter.emit(aliased_event_name, **kwargs)
           ~~~~~~~~~~~~~~~~~~^^^^^^^^^^^^^^^^^^^^^^^^^^^^^^
  File "/Users/martinlequerica/Documents/workspace/examen_qa/venv/lib/python3.13/site-packages/botocore/hooks.py", line 256, in emit
    return self._emit(event_name, kwargs)
           ~~~~~~~~~~^^^^^^^^^^^^^^^^^^^^
  File "/Users/martinlequerica/Documents/workspace/examen_qa/venv/lib/python3.13/site-packages/botocore/hooks.py", line 239, in _emit
    response = handler(**kwargs)
  File "/Users/martinlequerica/Documents/workspace/examen_qa/venv/lib/python3.13/site-packages/botocore/signers.py", line 108, in handler
    return self.sign(operation_name, request)
           ~~~~~~~~~^^^^^^^^^^^^^^^^^^^^^^^^^
  File "/Users/martinlequerica/Documents/workspace/examen_qa/venv/lib/python3.13/site-packages/botocore/signers.py", line 200, in sign
    auth.add_auth(request)
    ~~~~~~~~~~~~~^^^^^^^^^
  File "/Users/martinlequerica/Documents/workspace/examen_qa/venv/lib/python3.13/site-packages/botocore/auth.py", line 421, in add_auth
    raise NoCredentialsError()
botocore.exceptions.NoCredentialsError: Unable to locate credentials
2025-07-31 21:59:24,877 - task_service - WARNING - Connection attempt 2 failed. Retrying in 5 seconds...
2025-07-31 22:14:32,084 - __main__ - INFO - ================================================================================
2025-07-31 22:14:32,085 - __main__ - INFO - Starting Task Updater Service at 2025-07-31 22:14:32.085236
2025-07-31 22:14:32,085 - __main__ - INFO - Service Name: Task Updater Service
2025-07-31 22:14:32,085 - __main__ - INFO - Server running on http://localhost:8002
2025-07-31 22:14:32,085 - __main__ - INFO - RabbitMQ consumer started in background thread
2025-07-31 22:14:32,085 - __main__ - INFO - ================================================================================
2025-07-31 22:14:32,098 - task_service - INFO - Attempting to connect to SQS (Attempt 1/3)
2025-07-31 22:14:34,171 - task_service - ERROR - Error in SQS consumer: Unable to locate credentials
Traceback (most recent call last):
  File "/Users/martinlequerica/Documents/workspace/examen_qa/task_logger/task_service.py", line 128, in start_consumer
    queue_url = get_queue_url(sqs_client)
  File "/Users/martinlequerica/Documents/workspace/examen_qa/task_logger/task_service.py", line 107, in get_queue_url
    response = sqs_client.get_queue_url(QueueName=CONFIG['sqs']['queue_name'])
  File "/opt/anaconda3/envs/myenv/lib/python3.8/site-packages/botocore/client.py", line 565, in _api_call
    return self._make_api_call(operation_name, kwargs)
  File "/opt/anaconda3/envs/myenv/lib/python3.8/site-packages/botocore/client.py", line 999, in _make_api_call
    http, parsed_response = self._make_request(
  File "/opt/anaconda3/envs/myenv/lib/python3.8/site-packages/botocore/client.py", line 1023, in _make_request
    return self._endpoint.make_request(operation_model, request_dict)
  File "/opt/anaconda3/envs/myenv/lib/python3.8/site-packages/botocore/endpoint.py", line 119, in make_request
    return self._send_request(request_dict, operation_model)
  File "/opt/anaconda3/envs/myenv/lib/python3.8/site-packages/botocore/endpoint.py", line 196, in _send_request
    request = self.create_request(request_dict, operation_model)
  File "/opt/anaconda3/envs/myenv/lib/python3.8/site-packages/botocore/endpoint.py", line 132, in create_request
    self._event_emitter.emit(
  File "/opt/anaconda3/envs/myenv/lib/python3.8/site-packages/botocore/hooks.py", line 412, in emit
    return self._emitter.emit(aliased_event_name, **kwargs)
  File "/opt/anaconda3/envs/myenv/lib/python3.8/site-packages/botocore/hooks.py", line 256, in emit
    return self._emit(event_name, kwargs)
  File "/opt/anaconda3/envs/myenv/lib/python3.8/site-packages/botocore/hooks.py", line 239, in _emit
    response = handler(**kwargs)
  File "/opt/anaconda3/envs/myenv/lib/python3.8/site-packages/botocore/signers.py", line 105, in handler
    return self.sign(operation_name, request)
  File "/opt/anaconda3/envs/myenv/lib/python3.8/site-packages/botocore/signers.py", line 197, in sign
    auth.add_auth(request)
  File "/opt/anaconda3/envs/myenv/lib/python3.8/site-packages/botocore/auth.py", line 418, in add_auth
    raise NoCredentialsError()
botocore.exceptions.NoCredentialsError: Unable to locate credentials
2025-07-31 22:14:34,173 - task_service - WARNING - Connection attempt 1 failed. Retrying in 5 seconds...
2025-07-31 22:14:39,175 - task_service - INFO - Disconnected from SQS
2025-07-31 22:14:39,175 - task_service - INFO - Attempting to connect to SQS (Attempt 2/3)
2025-07-31 22:14:41,185 - task_service - ERROR - Error in SQS consumer: Unable to locate credentials
Traceback (most recent call last):
  File "/Users/martinlequerica/Documents/workspace/examen_qa/task_logger/task_service.py", line 128, in start_consumer
    queue_url = get_queue_url(sqs_client)
  File "/Users/martinlequerica/Documents/workspace/examen_qa/task_logger/task_service.py", line 107, in get_queue_url
    response = sqs_client.get_queue_url(QueueName=CONFIG['sqs']['queue_name'])
  File "/opt/anaconda3/envs/myenv/lib/python3.8/site-packages/botocore/client.py", line 565, in _api_call
    return self._make_api_call(operation_name, kwargs)
  File "/opt/anaconda3/envs/myenv/lib/python3.8/site-packages/botocore/client.py", line 999, in _make_api_call
    http, parsed_response = self._make_request(
  File "/opt/anaconda3/envs/myenv/lib/python3.8/site-packages/botocore/client.py", line 1023, in _make_request
    return self._endpoint.make_request(operation_model, request_dict)
  File "/opt/anaconda3/envs/myenv/lib/python3.8/site-packages/botocore/endpoint.py", line 119, in make_request
    return self._send_request(request_dict, operation_model)
  File "/opt/anaconda3/envs/myenv/lib/python3.8/site-packages/botocore/endpoint.py", line 196, in _send_request
    request = self.create_request(request_dict, operation_model)
  File "/opt/anaconda3/envs/myenv/lib/python3.8/site-packages/botocore/endpoint.py", line 132, in create_request
    self._event_emitter.emit(
  File "/opt/anaconda3/envs/myenv/lib/python3.8/site-packages/botocore/hooks.py", line 412, in emit
    return self._emitter.emit(aliased_event_name, **kwargs)
  File "/opt/anaconda3/envs/myenv/lib/python3.8/site-packages/botocore/hooks.py", line 256, in emit
    return self._emit(event_name, kwargs)
  File "/opt/anaconda3/envs/myenv/lib/python3.8/site-packages/botocore/hooks.py", line 239, in _emit
    response = handler(**kwargs)
  File "/opt/anaconda3/envs/myenv/lib/python3.8/site-packages/botocore/signers.py", line 105, in handler
    return self.sign(operation_name, request)
  File "/opt/anaconda3/envs/myenv/lib/python3.8/site-packages/botocore/signers.py", line 197, in sign
    auth.add_auth(request)
  File "/opt/anaconda3/envs/myenv/lib/python3.8/site-packages/botocore/auth.py", line 418, in add_auth
    raise NoCredentialsError()
botocore.exceptions.NoCredentialsError: Unable to locate credentials
2025-07-31 22:14:41,186 - task_service - WARNING - Connection attempt 2 failed. Retrying in 5 seconds...
2025-07-31 22:14:46,189 - task_service - INFO - Disconnected from SQS
2025-07-31 22:14:46,189 - task_service - INFO - Attempting to connect to SQS (Attempt 3/3)
2025-07-31 22:14:46,203 - task_service - ERROR - Error in SQS consumer: Unable to locate credentials
Traceback (most recent call last):
  File "/Users/martinlequerica/Documents/workspace/examen_qa/task_logger/task_service.py", line 128, in start_consumer
    queue_url = get_queue_url(sqs_client)
  File "/Users/martinlequerica/Documents/workspace/examen_qa/task_logger/task_service.py", line 107, in get_queue_url
    response = sqs_client.get_queue_url(QueueName=CONFIG['sqs']['queue_name'])
  File "/opt/anaconda3/envs/myenv/lib/python3.8/site-packages/botocore/client.py", line 565, in _api_call
    return self._make_api_call(operation_name, kwargs)
  File "/opt/anaconda3/envs/myenv/lib/python3.8/site-packages/botocore/client.py", line 999, in _make_api_call
    http, parsed_response = self._make_request(
  File "/opt/anaconda3/envs/myenv/lib/python3.8/site-packages/botocore/client.py", line 1023, in _make_request
    return self._endpoint.make_request(operation_model, request_dict)
  File "/opt/anaconda3/envs/myenv/lib/python3.8/site-packages/botocore/endpoint.py", line 119, in make_request
    return self._send_request(request_dict, operation_model)
  File "/opt/anaconda3/envs/myenv/lib/python3.8/site-packages/botocore/endpoint.py", line 196, in _send_request
    request = self.create_request(request_dict, operation_model)
  File "/opt/anaconda3/envs/myenv/lib/python3.8/site-packages/botocore/endpoint.py", line 132, in create_request
    self._event_emitter.emit(
  File "/opt/anaconda3/envs/myenv/lib/python3.8/site-packages/botocore/hooks.py", line 412, in emit
    return self._emitter.emit(aliased_event_name, **kwargs)
  File "/opt/anaconda3/envs/myenv/lib/python3.8/site-packages/botocore/hooks.py", line 256, in emit
    return self._emit(event_name, kwargs)
  File "/opt/anaconda3/envs/myenv/lib/python3.8/site-packages/botocore/hooks.py", line 239, in _emit
    response = handler(**kwargs)
  File "/opt/anaconda3/envs/myenv/lib/python3.8/site-packages/botocore/signers.py", line 105, in handler
    return self.sign(operation_name, request)
  File "/opt/anaconda3/envs/myenv/lib/python3.8/site-packages/botocore/signers.py", line 197, in sign
    auth.add_auth(request)
  File "/opt/anaconda3/envs/myenv/lib/python3.8/site-packages/botocore/auth.py", line 418, in add_auth
    raise NoCredentialsError()
botocore.exceptions.NoCredentialsError: Unable to locate credentials
2025-07-31 22:14:46,204 - task_service - ERROR - Max retries reached. Giving up.
2025-07-31 22:14:46,204 - task_service - INFO - Disconnected from SQS
2025-07-31 22:16:48,734 - __main__ - INFO - ================================================================================
2025-07-31 22:16:48,734 - __main__ - INFO - Starting Task Updater Service at 2025-07-31 22:16:48.734186
2025-07-31 22:16:48,734 - __main__ - INFO - Service Name: Task Updater Service
2025-07-31 22:16:48,734 - __main__ - INFO - Server running on http://localhost:8002
2025-07-31 22:16:48,734 - __main__ - INFO - RabbitMQ consumer started in background thread
2025-07-31 22:16:48,734 - __main__ - INFO - ================================================================================
2025-07-31 22:16:48,746 - task_service - INFO - Attempting to connect to SQS (Attempt 1/3)
2025-07-31 22:16:50,819 - task_service - ERROR - Error in SQS consumer: Unable to locate credentials
Traceback (most recent call last):
  File "/Users/martinlequerica/Documents/workspace/examen_qa/task_logger/task_service.py", line 128, in start_consumer
    queue_url = get_queue_url(sqs_client)
  File "/Users/martinlequerica/Documents/workspace/examen_qa/task_logger/task_service.py", line 107, in get_queue_url
    response = sqs_client.get_queue_url(QueueName=CONFIG['sqs']['queue_url'])
  File "/opt/anaconda3/envs/myenv/lib/python3.8/site-packages/botocore/client.py", line 565, in _api_call
    return self._make_api_call(operation_name, kwargs)
  File "/opt/anaconda3/envs/myenv/lib/python3.8/site-packages/botocore/client.py", line 999, in _make_api_call
    http, parsed_response = self._make_request(
  File "/opt/anaconda3/envs/myenv/lib/python3.8/site-packages/botocore/client.py", line 1023, in _make_request
    return self._endpoint.make_request(operation_model, request_dict)
  File "/opt/anaconda3/envs/myenv/lib/python3.8/site-packages/botocore/endpoint.py", line 119, in make_request
    return self._send_request(request_dict, operation_model)
  File "/opt/anaconda3/envs/myenv/lib/python3.8/site-packages/botocore/endpoint.py", line 196, in _send_request
    request = self.create_request(request_dict, operation_model)
  File "/opt/anaconda3/envs/myenv/lib/python3.8/site-packages/botocore/endpoint.py", line 132, in create_request
    self._event_emitter.emit(
  File "/opt/anaconda3/envs/myenv/lib/python3.8/site-packages/botocore/hooks.py", line 412, in emit
    return self._emitter.emit(aliased_event_name, **kwargs)
  File "/opt/anaconda3/envs/myenv/lib/python3.8/site-packages/botocore/hooks.py", line 256, in emit
    return self._emit(event_name, kwargs)
  File "/opt/anaconda3/envs/myenv/lib/python3.8/site-packages/botocore/hooks.py", line 239, in _emit
    response = handler(**kwargs)
  File "/opt/anaconda3/envs/myenv/lib/python3.8/site-packages/botocore/signers.py", line 105, in handler
    return self.sign(operation_name, request)
  File "/opt/anaconda3/envs/myenv/lib/python3.8/site-packages/botocore/signers.py", line 197, in sign
    auth.add_auth(request)
  File "/opt/anaconda3/envs/myenv/lib/python3.8/site-packages/botocore/auth.py", line 418, in add_auth
    raise NoCredentialsError()
botocore.exceptions.NoCredentialsError: Unable to locate credentials
2025-07-31 22:16:50,822 - task_service - WARNING - Connection attempt 1 failed. Retrying in 5 seconds...
2025-07-31 22:16:55,822 - task_service - INFO - Disconnected from SQS
2025-07-31 22:16:55,822 - task_service - INFO - Attempting to connect to SQS (Attempt 2/3)
2025-07-31 22:16:57,839 - task_service - ERROR - Error in SQS consumer: Unable to locate credentials
Traceback (most recent call last):
  File "/Users/martinlequerica/Documents/workspace/examen_qa/task_logger/task_service.py", line 128, in start_consumer
    queue_url = get_queue_url(sqs_client)
  File "/Users/martinlequerica/Documents/workspace/examen_qa/task_logger/task_service.py", line 107, in get_queue_url
    response = sqs_client.get_queue_url(QueueName=CONFIG['sqs']['queue_url'])
  File "/opt/anaconda3/envs/myenv/lib/python3.8/site-packages/botocore/client.py", line 565, in _api_call
    return self._make_api_call(operation_name, kwargs)
  File "/opt/anaconda3/envs/myenv/lib/python3.8/site-packages/botocore/client.py", line 999, in _make_api_call
    http, parsed_response = self._make_request(
  File "/opt/anaconda3/envs/myenv/lib/python3.8/site-packages/botocore/client.py", line 1023, in _make_request
    return self._endpoint.make_request(operation_model, request_dict)
  File "/opt/anaconda3/envs/myenv/lib/python3.8/site-packages/botocore/endpoint.py", line 119, in make_request
    return self._send_request(request_dict, operation_model)
  File "/opt/anaconda3/envs/myenv/lib/python3.8/site-packages/botocore/endpoint.py", line 196, in _send_request
    request = self.create_request(request_dict, operation_model)
  File "/opt/anaconda3/envs/myenv/lib/python3.8/site-packages/botocore/endpoint.py", line 132, in create_request
    self._event_emitter.emit(
  File "/opt/anaconda3/envs/myenv/lib/python3.8/site-packages/botocore/hooks.py", line 412, in emit
    return self._emitter.emit(aliased_event_name, **kwargs)
  File "/opt/anaconda3/envs/myenv/lib/python3.8/site-packages/botocore/hooks.py", line 256, in emit
    return self._emit(event_name, kwargs)
  File "/opt/anaconda3/envs/myenv/lib/python3.8/site-packages/botocore/hooks.py", line 239, in _emit
    response = handler(**kwargs)
  File "/opt/anaconda3/envs/myenv/lib/python3.8/site-packages/botocore/signers.py", line 105, in handler
    return self.sign(operation_name, request)
  File "/opt/anaconda3/envs/myenv/lib/python3.8/site-packages/botocore/signers.py", line 197, in sign
    auth.add_auth(request)
  File "/opt/anaconda3/envs/myenv/lib/python3.8/site-packages/botocore/auth.py", line 418, in add_auth
    raise NoCredentialsError()
botocore.exceptions.NoCredentialsError: Unable to locate credentials
2025-07-31 22:16:57,839 - task_service - WARNING - Connection attempt 2 failed. Retrying in 5 seconds...
2025-07-31 22:17:02,841 - task_service - INFO - Disconnected from SQS
2025-07-31 22:17:02,841 - task_service - INFO - Attempting to connect to SQS (Attempt 3/3)
2025-07-31 22:17:02,856 - task_service - ERROR - Error in SQS consumer: Unable to locate credentials
Traceback (most recent call last):
  File "/Users/martinlequerica/Documents/workspace/examen_qa/task_logger/task_service.py", line 128, in start_consumer
    queue_url = get_queue_url(sqs_client)
  File "/Users/martinlequerica/Documents/workspace/examen_qa/task_logger/task_service.py", line 107, in get_queue_url
    response = sqs_client.get_queue_url(QueueName=CONFIG['sqs']['queue_url'])
  File "/opt/anaconda3/envs/myenv/lib/python3.8/site-packages/botocore/client.py", line 565, in _api_call
    return self._make_api_call(operation_name, kwargs)
  File "/opt/anaconda3/envs/myenv/lib/python3.8/site-packages/botocore/client.py", line 999, in _make_api_call
    http, parsed_response = self._make_request(
  File "/opt/anaconda3/envs/myenv/lib/python3.8/site-packages/botocore/client.py", line 1023, in _make_request
    return self._endpoint.make_request(operation_model, request_dict)
  File "/opt/anaconda3/envs/myenv/lib/python3.8/site-packages/botocore/endpoint.py", line 119, in make_request
    return self._send_request(request_dict, operation_model)
  File "/opt/anaconda3/envs/myenv/lib/python3.8/site-packages/botocore/endpoint.py", line 196, in _send_request
    request = self.create_request(request_dict, operation_model)
  File "/opt/anaconda3/envs/myenv/lib/python3.8/site-packages/botocore/endpoint.py", line 132, in create_request
    self._event_emitter.emit(
  File "/opt/anaconda3/envs/myenv/lib/python3.8/site-packages/botocore/hooks.py", line 412, in emit
    return self._emitter.emit(aliased_event_name, **kwargs)
  File "/opt/anaconda3/envs/myenv/lib/python3.8/site-packages/botocore/hooks.py", line 256, in emit
    return self._emit(event_name, kwargs)
  File "/opt/anaconda3/envs/myenv/lib/python3.8/site-packages/botocore/hooks.py", line 239, in _emit
    response = handler(**kwargs)
  File "/opt/anaconda3/envs/myenv/lib/python3.8/site-packages/botocore/signers.py", line 105, in handler
    return self.sign(operation_name, request)
  File "/opt/anaconda3/envs/myenv/lib/python3.8/site-packages/botocore/signers.py", line 197, in sign
    auth.add_auth(request)
  File "/opt/anaconda3/envs/myenv/lib/python3.8/site-packages/botocore/auth.py", line 418, in add_auth
    raise NoCredentialsError()
botocore.exceptions.NoCredentialsError: Unable to locate credentials
2025-07-31 22:17:02,857 - task_service - ERROR - Max retries reached. Giving up.
2025-07-31 22:17:02,857 - task_service - INFO - Disconnected from SQS
2025-07-31 22:19:32,503 - __main__ - INFO - ================================================================================
2025-07-31 22:19:32,503 - __main__ - INFO - Starting Task Updater Service at 2025-07-31 22:19:32.503131
2025-07-31 22:19:32,503 - __main__ - INFO - Service Name: Task Updater Service
2025-07-31 22:19:32,503 - __main__ - INFO - Server running on http://localhost:8002
2025-07-31 22:19:32,503 - __main__ - INFO - RabbitMQ consumer started in background thread
2025-07-31 22:19:32,503 - __main__ - INFO - ================================================================================
2025-07-31 22:19:32,516 - task_service - INFO - Attempting to connect to SQS (Attempt 1/3)
2025-07-31 22:19:32,582 - task_service - INFO - Queue http://sqs.us-east-1.localhost.localstack.cloud:4566/000000000000/task_consumer_queue does not exist. Creating it...
2025-07-31 22:19:32,588 - task_service - ERROR - Error in SQS consumer: An error occurred (InvalidParameterValue) when calling the CreateQueue operation: Can only include alphanumeric characters, hyphens, or underscores. 1 to 80 in length
Traceback (most recent call last):
  File "/Users/martinlequerica/Documents/workspace/examen_qa/task_logger/task_service.py", line 109, in get_queue_url
    response = sqs_client.get_queue_url(QueueName=CONFIG['sqs']['queue_url'])
  File "/opt/anaconda3/envs/myenv/lib/python3.8/site-packages/botocore/client.py", line 565, in _api_call
    return self._make_api_call(operation_name, kwargs)
  File "/opt/anaconda3/envs/myenv/lib/python3.8/site-packages/botocore/client.py", line 1017, in _make_api_call
    raise error_class(parsed_response, operation_name)
botocore.errorfactory.QueueDoesNotExist: An error occurred (AWS.SimpleQueueService.NonExistentQueue) when calling the GetQueueUrl operation: The specified queue does not exist.

During handling of the above exception, another exception occurred:

Traceback (most recent call last):
  File "/Users/martinlequerica/Documents/workspace/examen_qa/task_logger/task_service.py", line 130, in start_consumer
    queue_url = get_queue_url(sqs_client)
  File "/Users/martinlequerica/Documents/workspace/examen_qa/task_logger/task_service.py", line 113, in get_queue_url
    response = sqs_client.create_queue(QueueName=CONFIG['sqs']['queue_url'])
  File "/opt/anaconda3/envs/myenv/lib/python3.8/site-packages/botocore/client.py", line 565, in _api_call
    return self._make_api_call(operation_name, kwargs)
  File "/opt/anaconda3/envs/myenv/lib/python3.8/site-packages/botocore/client.py", line 1017, in _make_api_call
    raise error_class(parsed_response, operation_name)
botocore.exceptions.ClientError: An error occurred (InvalidParameterValue) when calling the CreateQueue operation: Can only include alphanumeric characters, hyphens, or underscores. 1 to 80 in length
2025-07-31 22:19:32,589 - task_service - WARNING - Connection attempt 1 failed. Retrying in 5 seconds...
2025-07-31 22:19:37,592 - task_service - INFO - Disconnected from SQS
2025-07-31 22:19:37,592 - task_service - INFO - Attempting to connect to SQS (Attempt 2/3)
2025-07-31 22:19:37,625 - task_service - INFO - Queue http://sqs.us-east-1.localhost.localstack.cloud:4566/000000000000/task_consumer_queue does not exist. Creating it...
2025-07-31 22:19:37,639 - task_service - ERROR - Error in SQS consumer: An error occurred (InvalidParameterValue) when calling the CreateQueue operation: Can only include alphanumeric characters, hyphens, or underscores. 1 to 80 in length
Traceback (most recent call last):
  File "/Users/martinlequerica/Documents/workspace/examen_qa/task_logger/task_service.py", line 109, in get_queue_url
    response = sqs_client.get_queue_url(QueueName=CONFIG['sqs']['queue_url'])
  File "/opt/anaconda3/envs/myenv/lib/python3.8/site-packages/botocore/client.py", line 565, in _api_call
    return self._make_api_call(operation_name, kwargs)
  File "/opt/anaconda3/envs/myenv/lib/python3.8/site-packages/botocore/client.py", line 1017, in _make_api_call
    raise error_class(parsed_response, operation_name)
botocore.errorfactory.QueueDoesNotExist: An error occurred (AWS.SimpleQueueService.NonExistentQueue) when calling the GetQueueUrl operation: The specified queue does not exist.

During handling of the above exception, another exception occurred:

Traceback (most recent call last):
  File "/Users/martinlequerica/Documents/workspace/examen_qa/task_logger/task_service.py", line 130, in start_consumer
    queue_url = get_queue_url(sqs_client)
  File "/Users/martinlequerica/Documents/workspace/examen_qa/task_logger/task_service.py", line 113, in get_queue_url
    response = sqs_client.create_queue(QueueName=CONFIG['sqs']['queue_url'])
  File "/opt/anaconda3/envs/myenv/lib/python3.8/site-packages/botocore/client.py", line 565, in _api_call
    return self._make_api_call(operation_name, kwargs)
  File "/opt/anaconda3/envs/myenv/lib/python3.8/site-packages/botocore/client.py", line 1017, in _make_api_call
    raise error_class(parsed_response, operation_name)
botocore.exceptions.ClientError: An error occurred (InvalidParameterValue) when calling the CreateQueue operation: Can only include alphanumeric characters, hyphens, or underscores. 1 to 80 in length
2025-07-31 22:19:37,639 - task_service - WARNING - Connection attempt 2 failed. Retrying in 5 seconds...
2025-07-31 22:19:42,644 - task_service - INFO - Disconnected from SQS
2025-07-31 22:19:42,644 - task_service - INFO - Attempting to connect to SQS (Attempt 3/3)
2025-07-31 22:19:42,682 - task_service - INFO - Queue http://sqs.us-east-1.localhost.localstack.cloud:4566/000000000000/task_consumer_queue does not exist. Creating it...
2025-07-31 22:19:42,692 - task_service - ERROR - Error in SQS consumer: An error occurred (InvalidParameterValue) when calling the CreateQueue operation: Can only include alphanumeric characters, hyphens, or underscores. 1 to 80 in length
Traceback (most recent call last):
  File "/Users/martinlequerica/Documents/workspace/examen_qa/task_logger/task_service.py", line 109, in get_queue_url
    response = sqs_client.get_queue_url(QueueName=CONFIG['sqs']['queue_url'])
  File "/opt/anaconda3/envs/myenv/lib/python3.8/site-packages/botocore/client.py", line 565, in _api_call
    return self._make_api_call(operation_name, kwargs)
  File "/opt/anaconda3/envs/myenv/lib/python3.8/site-packages/botocore/client.py", line 1017, in _make_api_call
    raise error_class(parsed_response, operation_name)
botocore.errorfactory.QueueDoesNotExist: An error occurred (AWS.SimpleQueueService.NonExistentQueue) when calling the GetQueueUrl operation: The specified queue does not exist.

During handling of the above exception, another exception occurred:

Traceback (most recent call last):
  File "/Users/martinlequerica/Documents/workspace/examen_qa/task_logger/task_service.py", line 130, in start_consumer
    queue_url = get_queue_url(sqs_client)
  File "/Users/martinlequerica/Documents/workspace/examen_qa/task_logger/task_service.py", line 113, in get_queue_url
    response = sqs_client.create_queue(QueueName=CONFIG['sqs']['queue_url'])
  File "/opt/anaconda3/envs/myenv/lib/python3.8/site-packages/botocore/client.py", line 565, in _api_call
    return self._make_api_call(operation_name, kwargs)
  File "/opt/anaconda3/envs/myenv/lib/python3.8/site-packages/botocore/client.py", line 1017, in _make_api_call
    raise error_class(parsed_response, operation_name)
botocore.exceptions.ClientError: An error occurred (InvalidParameterValue) when calling the CreateQueue operation: Can only include alphanumeric characters, hyphens, or underscores. 1 to 80 in length
2025-07-31 22:19:42,693 - task_service - ERROR - Max retries reached. Giving up.
2025-07-31 22:19:42,693 - task_service - INFO - Disconnected from SQS
2025-07-31 22:20:45,699 - __main__ - INFO - ================================================================================
2025-07-31 22:20:45,700 - __main__ - INFO - Starting Task Updater Service at 2025-07-31 22:20:45.699997
2025-07-31 22:20:45,700 - __main__ - INFO - Service Name: Task Updater Service
2025-07-31 22:20:45,700 - __main__ - INFO - Server running on http://localhost:8002
2025-07-31 22:20:45,700 - __main__ - INFO - RabbitMQ consumer started in background thread
2025-07-31 22:20:45,700 - __main__ - INFO - ================================================================================
2025-07-31 22:20:45,711 - task_service - INFO - Attempting to connect to SQS (Attempt 1/3)
2025-07-31 22:20:45,781 - task_service - INFO - Successfully connected to SQS
2025-07-31 22:20:45,781 - task_service - INFO - Listening for messages on queue: http://sqs.us-east-1.localhost.localstack.cloud:4566/000000000000/task_consumer_queue
2025-07-31 22:20:45,781 - task_service - INFO - Press CTRL+C to exit
2025-07-31 22:20:45,796 - task_service - INFO - Processing message - Task ID: 8a77047f-42be-4ba3-a5ad-d622fef70e27, Action: create
2025-07-31 22:20:45,796 - task_service - INFO - Creating/Updating task - ID: 8a77047f-42be-4ba3-a5ad-d622fef70e27
2025-07-31 22:20:45,796 - task_service - INFO - Task Name: asasdasdasdasd
2025-07-31 22:20:45,796 - task_service - INFO - Description: asdasdasdasd
2025-07-31 22:20:45,796 - task_service - INFO - Assignee: asdasdads
2025-07-31 22:20:45,796 - task_service - INFO - Status: N/A
2025-07-31 22:20:45,796 - task_service - INFO - Successfully processed message for task ID: 8a77047f-42be-4ba3-a5ad-d622fef70e27
2025-07-31 22:20:55,954 - task_service - INFO - Processing message - Task ID: beac8000-ade2-46d1-bf5a-d65795800d16, Action: create
2025-07-31 22:20:55,955 - task_service - INFO - Creating/Updating task - ID: beac8000-ade2-46d1-bf5a-d65795800d16
2025-07-31 22:20:55,955 - task_service - INFO - Task Name: asd
2025-07-31 22:20:55,955 - task_service - INFO - Description: asd
2025-07-31 22:20:55,956 - task_service - INFO - Assignee: asd
2025-07-31 22:20:55,956 - task_service - INFO - Status: N/A
2025-07-31 22:20:55,956 - task_service - INFO - Successfully processed message for task ID: beac8000-ade2-46d1-bf5a-d65795800d16
